Workbook

Sheet IS
B1: =BS!B1 -> Particular | C1: =BS!C1 -> 44286 | D1: =BS!D1 -> 44651 | E1: =BS!E1 -> 45016 | F1: =BS!F1 -> 45382 | G1: =BS!G1 -> 45747 | H1: =BS!H1 -> 46112 | I1: =BS!I1 -> 46477 | ... L1: =BS!L1 -> 47573
B2: INCOME
B3: Revenue from operations | C3: 135979.03 | D3: 156521.23 | E3: 183340.7 | F3: 221112.91 | G3: 255734.45 | H3: ='NOTES '!H29 -> 292483.16 | I3: ='NOTES '!I29 -> 334843.03 | J3: ='NOTES '!J29 -> 383693 | K3: ='NOTES '!K29 -> 440052.95 | L3: ='NOTES '!L29 -> 505106.96
B4: Other income (net) | C4: 3429.35 | D4: 2267.08 | E4: 2929.17 | F4: 4158.03 | G4: 4124.82 | H4: ='NOTES '!H32 -> 4454.8056 | I4: ='NOTES '!I32 -> 4811.19 | J4: ='NOTES '!J32 -> 5196.0853 | K4: ='NOTES '!K32 -> 5611.7721 | L4: ='NOTES '!L32 -> 6060.7138
B5: Total Income | C5: =SUM(C3:C4) -> 139408.38 | D5: =SUM(D3:D4) -> 158788.31 | E5: =SUM(E3:E4) -> 186269.87 | F5: =SUM(F3:F4) -> 225270.94 | G5: =SUM(G3:G4) -> 259859.27 | H5: =SUM(H3:H4) -> 296937.96 | I5: =SUM(I3:I4) -> 339654.22 | J5: =SUM(J3:J4) -> 388889.08 | ... L5: =SUM(L3:L4) -> 511167.67
L6: -
B7: EXPENSES
B8: Manufacturing, construction and Operating Exp.
B9: Cost of raw materials & components | C9: 15562.05 | D9: 17100.84 | E9: 18995.11 | F9: 19442.25 | G9: 27655.02 | H9: ='NOTES '!H34 -> 30973.622 | I9: ='NOTES '!I34 -> 34690.457 | J9: ='NOTES '!J34 -> 38853.312 | K9: ='NOTES '!K34 -> 43515.709 | L9: ='NOTES '!L34 -> 48737.594
B10: Construction materials consumed | C10: 24558.23 | D10: 33506.21 | E10: 43237.35 | F10: 54813.97 | G10: 63526.44 | H10: ='NOTES '!H35 -> 77502.257 | I10: ='NOTES '!I35 -> 94552.753 | J10: ='NOTES '!J35 -> 115354.36 | K10: ='NOTES '!K35 -> 140732.32 | L10: ='NOTES '!L35 -> 171693.43
B11: Purchase of stock-in-trade | C11: 1213.58 | D11: 1069.5 | E11: 1052.86 | F11: 1063.77 | G11: 1402.14 | H11: ='NOTES '!H36 -> 1410.893 | I11: ='NOTES '!I36 -> 1419.7006 | J11: ='NOTES '!J36 -> 1428.5631 | K11: ='NOTES '!K36 -> 1437.481 | L11: ='NOTES '!L36 -> 1446.4546
B12: Stores, spares and tools consumed | C12: 2032.89 | D12: 3091.07 | E12: 4814.89 | F12: 4432.02 | G12: 4393.39 | H12: ='NOTES '!H37 -> 4478.8068 | I12: ='NOTES '!I37 -> 4565.8842 | J12: ='NOTES '!J37 -> 4654.6546 | K12: ='NOTES '!K37 -> 4745.1509 | L12: ='NOTES '!L37 -> 4837.4066
B13: Sub-contracting charges | C13: 22316.18 | D13: 24772.33 | E13: 25624.45 | F13: 35054.35 | G13: 40570.92 | H13: ='NOTES '!H38 -> 46807.798 | I13: ='NOTES '!I38 -> 54003.459 | J13: ='NOTES '!J38 -> 62305.292 | K13: ='NOTES '!K38 -> 71883.347 | L13: ='NOTES '!L38 -> 82933.817
B14: Changes in inventories (Finished/WIP) | C14: 343.37 | D14: -2076.6 | E14: -3156.64 | F14: 1021.07 | G14: -410.79 | H14: ='NOTES '!H39 -> -408.72682 | I14: ='NOTES '!I39 -> -406.67401 | J14: ='NOTES '!J39 -> -404.63151 | K14: ='NOTES '!K39 -> -402.59926 | L14: ='NOTES '!L39 -> -400.57722
B15: Other mfg., const. & operating expenses | C15: 12983.56 | D15: 16322.62 | E15: 20020.81 | F15: 24486.49 | G15: 27533.55 | H15: ='NOTES '!H40 -> 30562.241 | I15: ='NOTES '!I40 -> 33924.087 | J15: ='NOTES '!J40 -> 37655.737 | K15: ='NOTES '!K40 -> 41797.868 | L15: ='NOTES '!L40 -> 46395.633
B16: Finance cost (Financial Services) | C16: 7691.04 | D16: 5952.54 | E16: 6026.44 | F16: 5714.9 | G16: 6302.23 | H16: ='NOTES '!H41 -> 6521.8839 | I16: ='NOTES '!I41 -> 6749.1935 | J16: ='NOTES '!J41 -> 6984.4256 | K16: ='NOTES '!K41 -> 7227.8564 | L16: ='NOTES '!L41 -> 7479.7715
B17: COGS | C17: =SUM(C9:C16) -> 86700.9 | D17: =SUM(D9:D16) -> 99738.51 | E17: =SUM(E9:E16) -> 116615.27 | F17: =SUM(F9:F16) -> 146028.82 | G17: =SUM(G9:G16) -> 170972.9 | H17: =SUM(H9:H16) -> 197848.77 | I17: =SUM(I9:I16) -> 229498.86 | J17: =SUM(J9:J16) -> 266831.71 | ... L17: =SUM(L9:L16) -> 363123.53
B18: GROSS PROFIT | C18: =C3-C17+C4 -> 52707.48 | D18: =D3-D17+D4 -> 59049.8 | E18: =E3-E17+E4 -> 69654.6 | F18: =F3-F17+F4 -> 79242.12 | G18: =G3-G17+G4 -> 88886.37 | H18: =H3-H17+H4 -> 99089.189 | I18: =I3-I17+I4 -> 110155.36 | J18: =J3-J17+J4 -> 122057.37 | ... L18: =L3-L17+L4 -> 148044.14
L19: -
B20: Employee benefits expense | C20: 24750.54 | D20: 29733.53 | E20: 37214.11 | F20: 41171.02 | G20: 46768.68 | H20: ='NOTES '!H44 -> 46797.305 | I20: ='NOTES '!I44 -> 53574.885 | J20: ='NOTES '!J44 -> 61390.879 | K20: ='NOTES '!K44 -> 70408.472 | L20: ='NOTES '!L44 -> 80817.113
B21: Sales, administration and other expenses | C21: 8903.49 | D21: 8831.89 | E21: 8758.04 | F21: 10419.42 | G21: 11558.13 | H21: ='NOTES '!H45 -> 8774.4948 | I21: ='NOTES '!I45 -> 10045.291 | J21: ='NOTES '!J45 -> 11510.79 | K21: ='NOTES '!K45 -> 13201.588 | L21: ='NOTES '!L45 -> 15153.209
B22: Total Expenses | C22: =SUM(C20:C21) -> 33654.03 | D22: =SUM(D20:D21) -> 38565.42 | E22: =SUM(E20:E21) -> 45972.15 | F22: =SUM(F20:F21) -> 51590.44 | G22: =SUM(G20:G21) -> 58326.81 | H22: =SUM(H20:H21) -> 55571.8 | I22: =SUM(I20:I21) -> 63620.176 | J22: =SUM(J20:J21) -> 72901.669 | ... L22: =SUM(L20:L21) -> 95970.322
B23: EBITDA | C23: =C18-C22 -> 19053.45 | D23: =D18-D22 -> 20484.38 | E23: =E18-E22 -> 23682.45 | F23: =F18-F22 -> 27651.68 | G23: =G18-G22 -> 30559.56 | H23: =H18-H22 -> 43517.389 | I23: =I18-I22 -> 46535.186 | J23: =J18-J22 -> 49155.701 | ... L23: =L18-L22 -> 52073.82
L24: -
B25: Depreciation and amortisation | C25: 2904.21 | D25: 2947.95 | E25: 3502.25 | F25: 3682.33 | G25: 4121.18 | H25: ='NOTES '!H79 -> 4389.1667 | I25: ='NOTES '!I79 -> 4790.8513 | J25: ='NOTES '!J79 -> 5247.6594 | K25: ='NOTES '!K79 -> 5767.8142 | L25: ='NOTES '!L79 -> 6360.8169
B26: EBIT | C26: =C23-C25 -> 16149.24 | D26: =D23-D25 -> 17536.43 | E26: =E23-E25 -> 20180.2 | F26: =F23-F25 -> 23969.35 | G26: =G23-G25 -> 26438.38 | H26: =H23-H25 -> 39128.222 | I26: =I23-I25 -> 41744.335 | J26: =J23-J25 -> 43908.042 | ... L26: =L23-L25 -> 45713.003
L27: -
B28: Exceptional items (net of tax) | C28: -3693.78 | D28: 119.7 | E28: -91.97 | F28: 114.44 | G28: 474.78 | H28: =G28 -> 474.78 | I28: =H28 -> 474.78 | J28: =I28 -> 474.78 | K28: =J28 -> 474.78 | L28: =K28 -> 474.78
B29: Finance costs (Corporate) | C29: -3913.44 | D29: -3125.7 | E29: -3207.16 | F29: -3545.85 | G29: -3334.37 | H29: =-'NOTES '!H83 -> -3510.317 | I29: =-'NOTES '!I83 -> -3695.5483 | J29: =-'NOTES '!J83 -> -3890.5538 | K29: =-'NOTES '!K83 -> -4095.8493 | L29: =-'NOTES '!L83 -> -4311.9778
L30: -
B31: Profit before tax | C31: =SUM(C26:C29) -> 8542.02 | D31: =SUM(D26:D29) -> 14530.43 | E31: =SUM(E26:E29) -> 16881.07 | F31: =SUM(F26:F29) -> 20537.94 | G31: =SUM(G26:G29) -> 23578.79 | H31: =SUM(H26:H29) -> 36092.685 | I31: =SUM(I26:I29) -> 38523.566 | J31: =SUM(J26:J29) -> 40492.268 | ... L31: =SUM(L26:L29) -> 41875.805
L32: -
B33: TAX | C33: -4010.82 | D33: -4216.61 | E33: -4484.16 | F33: -4947.39 | G33: -5891.4 | H33: =-25%*H31 -> -9023.1713 | I33: =-25%*I31 -> -9630.8916 | J33: =-25%*J31 -> -10123.067 | K33: =-25%*K31 -> -10432.161 | L33: =-25%*L31 -> -10468.951
L34: -
B35: Profit after tax | C35: =SUM(C31:C33) -> 4531.2 | D35: =SUM(D31:D33) -> 10313.82 | E35: =SUM(E31:E33) -> 12396.91 | F35: =SUM(F31:F33) -> 15590.55 | G35: =SUM(G31:G33) -> 17687.39 | H35: =SUM(H31:H33) -> 27069.514 | I35: =SUM(I31:I33) -> 28892.675 | J35: =SUM(J31:J33) -> 30369.201 | ... L35: =SUM(L31:L33) -> 31406.854
B37: EPS | C37: =(C35/C38)*10000000 -> 32.260745 | D37: =(D35/D38)*10000000 -> 73.40645 | E37: =(E35/E38)*10000000 -> 88.203964 | F37: =(F35/F38)*10000000 -> 113.41315 | G37: =(G35/G38)*10000000 -> 128.61759 | H37: =(H35/H38)*10000000 -> 196.84168 | I37: =(I35/I38)*10000000 -> 210.09918 | J37: =(J35/J38)*10000000 -> 220.83605 | ... L37: =(L35/L38)*10000000 -> 228.38157
B38: Outstanding share | C38: 1404555297 | D38: 1405029123 | E38: 1405482190 | F38: 1374668619 | G38: 1375192165 | H38: 1375192165 | I38: 1375192165 | J38: 1375192165 | K38: 1375192165 | L38: 1375192165

Sheet BS
B1: Particular | C1: 44286 | D1: =EDATE(C1,12) -> 44651 | E1: =EDATE(D1,12) -> 45016 | F1: =EDATE(E1,12) -> 45382 | G1: =EDATE(F1,12) -> 45747 | H1: =EDATE(G1,12) -> 46112 | I1: =EDATE(H1,12) -> 46477 | J1: =EDATE(I1,12) -> 46843 | K1: =EDATE(J1,12) -> 47208 | L1: =EDATE(K1,12) -> 47573
B2: Non-current assets
B3: Property, plant and equipment | C3: 11386.29 | D3: 10578.87 | E3: 11336.28 | F3: 13297.64 | G3: 14128.56 | H3: ='NOTES '!H53 -> 15025.506 | I3: ='NOTES '!I53 -> 16112.805 | J3: ='NOTES '!J53 -> 17422.222 | K3: ='NOTES '!K53 -> 18990.69 | L3: ='NOTES '!L53 -> 20861.17
B4: Capital work-in-progress | C4: 388.37 | D4: 1170.32 | E4: 2949.09 | F4: 2897.04 | G4: 2390.86 | H4: =G4 -> 2390.86 | I4: =H4 -> 2390.86 | J4: =I4 -> 2390.86 | K4: =J4 -> 2390.86 | L4: =K4 -> 2390.86
B5: Investment property | C5: 3646.78 | D5: 3962.98 | E5: 3360.22 | F5: 1936.44 | G5: 1157.33 | H5: ='NOTES '!H61 -> 1131.2573 | I5: ='NOTES '!I61 -> 1108.166 | J5: ='NOTES '!J61 -> 1088.5226 | K5: ='NOTES '!K61 -> 1072.8678 | L5: ='NOTES '!L61 -> 1061.8279
B6: Investment property under construction | F6: 254.93 | G6: 501.3 | H6: =G6 -> 501.3 | I6: =H6 -> 501.3 | J6: =I6 -> 501.3 | K6: =J6 -> 501.3 | L6: =K6 -> 501.3
B7: Goodwill | C7: 8066.96 | D7: 7476.98 | E7: 7798.65 | F7: 7800.88 | G7: 8348.48 | H7: =G7 -> 8348.48 | I7: =H7 -> 8348.48 | J7: =I7 -> 8348.48 | K7: =J7 -> 8348.48 | L7: =K7 -> 8348.48
B8: Other intangible assets | C8: 19197.76 | D8: 18729.37 | E8: 18007.98 | F8: 17384.52 | G8: 17050.76 | H8: ='NOTES '!H74 -> 16686.322 | I8: ='NOTES '!I74 -> 16383.132 | J8: ='NOTES '!J74 -> 16150.78 | K8: ='NOTES '!K74 -> 16000.38 | L8: ='NOTES '!L74 -> 15944.813
B9: Intangible assets under development | C9: 112.02 | D9: 79.23 | E9: 116.48 | F9: 147.97 | G9: 197.82 | H9: =G9 -> 197.82 | I9: =H9 -> 197.82 | J9: =I9 -> 197.82 | K9: =J9 -> 197.82 | L9: =K9 -> 197.82
B10: Right-of-use assets | C10: 2021.53 | D10: 1988.62 | E10: 2137.87 | F10: 2289.41 | G10: 2869.02 | H10: =G10+'NOTES '!H64-'NOTES '!H65 -> 3275.7853 | I10: =H10+'NOTES '!I64-'NOTES '!I65 -> 3790.8932 | J10: =I10+'NOTES '!J64-'NOTES '!J65 -> 4434.5447 | K10: =J10+'NOTES '!K64-'NOTES '!K65 -> 5230.3635 | L10: =K10+'NOTES '!L64-'NOTES '!L65 -> 6205.9634
B11: Financial assets
B12: Investments in joint ventures and associates | C12: 2670.26 | D12: 2729.35 | E12: 1304.86 | F12: 1264.25 | G12: 2318.42 | H12: =G12 -> 2318.42 | I12: =H12 -> 2318.42 | J12: =I12 -> 2318.42 | K12: =J12 -> 2318.42 | L12: =K12 -> 2318.42
B13: Other investments | C13: 5945.14 | D13: 7081.51 | E13: 7920.03 | F13: 9425.94 | G13: 9126.23 | H13: =G13 -> 9126.23 | I13: =H13 -> 9126.23 | J13: =I13 -> 9126.23 | K13: =J13 -> 9126.23 | L13: =K13 -> 9126.23
B14: Loans towards financing activities | C14: 52631.67 | D14: 46736.84 | E14: 40920.92 | F14: 52154.76 | G14: 62847.35 | H14: =G14 -> 62847.35 | I14: =H14 -> 62847.35 | J14: =I14 -> 62847.35 | K14: =J14 -> 62847.35 | L14: =K14 -> 62847.35
B15: Other loans | C15: 173.24 | D15: 252.99 | E15: 356 | F15: 475.46 | G15: 348.96 | H15: =G15 -> 348.96 | I15: =H15 -> 348.96 | J15: =I15 -> 348.96 | K15: =J15 -> 348.96 | L15: =K15 -> 348.96
B16: Other financial assets | C16: 1420.19 | D16: 2162.97 | E16: 1965.78 | F16: 1952.08 | G16: 1863.04 | H16: =G16 -> 1863.04 | I16: =H16 -> 1863.04 | J16: =I16 -> 1863.04 | K16: =J16 -> 1863.04 | L16: =K16 -> 1863.04
C17: =SUM(C12:C16) -> 62840.5 | D17: =SUM(D12:D16) -> 58963.66 | E17: =SUM(E12:E16) -> 52467.59 | F17: =SUM(F12:F16) -> 65272.49 | G17: =SUM(G12:G16) -> 76504 | H17: =SUM(H12:H16) -> 76504 | I17: =SUM(I12:I16) -> 76504 | J17: =SUM(J12:J16) -> 76504 | ... L17: =SUM(L12:L16) -> 76504
B18: Deferred tax assets (net) | C18: 2697 | D18: 2840.1 | E18: 3984.79 | F18: 3863.72 | G18: 3792.88 | H18: 3792.88 | I18: 3792.88 | J18: 3792.88 | K18: 3792.88 | L18: 3792.88
B19: Current Tax Assets (net) | F19: 4245.78 | G19: 4581.6 | H19: 4581.6 | I19: 4581.6 | J19: 4581.6 | K19: 4581.6 | L19: 4581.6
B20: Other non-current assets | C20: 5949.67 | D20: 6077.62 | E20: 5989.04 | F20: 2156.55 | G20: 2659.78 | H20: 2659.78 | I20: 2659.78 | J20: 2659.78 | K20: 2659.78 | L20: 2659.78
B21: Total non-current assets | C21: =SUM(C3:C10,C17:C20) -> 116306.88 | D21: =SUM(D3:D10,D17:D20) -> 111867.75 | E21: =SUM(E3:E10,E17:E20) -> 108147.99 | F21: =SUM(F3:F10,F17:F20) -> 121547.37 | G21: =SUM(G3:G10,G17:G20) -> 134182.39 | H21: =SUM(H3:H10,H17:H20) -> 135095.59 | I21: =SUM(I3:I10,I17:I20) -> 136371.72 | J21: =SUM(J3:J10,J17:J20) -> 138072.79 | ... L21: =SUM(L3:L10,L17:L20) -> 143050.5
B23: Current assets
B24: Inventories | C24: 5820.54 | D24: 5943.32 | E24: 6828.78 | F24: 6620.19 | G24: 7670.55 | H24: ='NOTES '!H85 -> 8774.4948 | I24: ='NOTES '!I85 -> 10045.291 | J24: ='NOTES '!J85 -> 11510.79 | K24: ='NOTES '!K85 -> 13201.588 | L24: ='NOTES '!L85 -> 15153.209
B25: Financial assets
B26: Investments | C26: 31011.23 | D26: 29792.51 | E26: 35573.42 | F26: 34957.63 | G26: 43360.62 | H26: =G26 -> 43360.62 | I26: =H26 -> 43360.62 | J26: =I26 -> 43360.62 | K26: =J26 -> 43360.62 | L26: =K26 -> 43360.62
B27: Trade receivables | C27: 42229.78 | D27: 46138.92 | E27: 44731.53 | F27: 48770.95 | G27: 53713.68 | H27: =G27 -> 53713.68 | I27: =H27 -> 53713.68 | J27: =I27 -> 53713.68 | K27: =J27 -> 53713.68 | L27: =K27 -> 53713.68
B28: Cash and cash equivalents | C28: 13373.52 | D28: 13770.24 | E28: 16926.69 | F28: 11958.5 | G28: 12187 | H28: =CFS!C19 -> 37239.368 | I28: =CFS!D19 -> 63585.122 | J28: =CFS!E19 -> 90787.751 | K28: =CFS!F19 -> 118195.2 | L28: =CFS!G19 -> 144870.96
B29: Other bank balances | C29: 2867.98 | D29: 5182.93 | E29: 5592.91 | F29: 3399.89 | G29: 10778.34 | H29: =G29 -> 10778.34 | I29: =H29 -> 10778.34 | J29: =I29 -> 10778.34 | K29: =J29 -> 10778.34 | L29: =K29 -> 10778.34
B30: Loans towards financing activities | C30: 41379.03 | D30: 42269.2 | E30: 40460.55 | F30: 34814.59 | G30: 36077.51 | H30: =G30 -> 36077.51 | I30: =H30 -> 36077.51 | J30: =I30 -> 36077.51 | K30: =J30 -> 36077.51 | L30: =K30 -> 36077.51
B31: Other loans | C31: 235.35 | D31: 280.34 | E31: 251.15 | F31: 106.54 | G31: 416.85 | H31: =G31 -> 416.85 | I31: =H31 -> 416.85 | J31: =I31 -> 416.85 | K31: =J31 -> 416.85 | L31: =K31 -> 416.85
B32: Other financial assets | C32: 3251.68 | D32: 3840.04 | E32: 4930.1 | F32: 5563.92 | G32: 5419.89 | H32: =G32 -> 5419.89 | I32: =H32 -> 5419.89 | J32: =I32 -> 5419.89 | K32: =J32 -> 5419.89 | L32: =K32 -> 5419.89
C33: =SUM(C26:C32) -> 134348.57 | D33: =SUM(D26:D32) -> 141274.18 | E33: =SUM(E26:E32) -> 148466.35 | F33: =SUM(F26:F32) -> 139572.02 | G33: =SUM(G26:G32) -> 161953.89 | H33: =SUM(H26:H32) -> 187006.26 | I33: =SUM(I26:I32) -> 213352.01 | J33: =SUM(J26:J32) -> 240554.64 | ... L33: =SUM(L26:L32) -> 294637.85
B34: Other current assets | C34: 54791.48 | D34: 60132.89 | E34: 65920.39 | F34: 71391.03 | G34: 75559.83 | H34: =G34 -> 75559.83 | I34: =H34 -> 75559.83 | J34: =I34 -> 75559.83 | K34: =J34 -> 75559.83 | L34: =K34 -> 75559.83
B35: Total current assets | C35: =SUM(C24,C33:C34) -> 194960.59 | D35: =SUM(D24,D33:D34) -> 207350.39 | E35: =SUM(E24,E33:E34) -> 221215.52 | F35: =SUM(F24,F33:F34) -> 217583.24 | G35: =SUM(G24,G33:G34) -> 245184.27 | H35: =SUM(H24,H33:H34) -> 271340.58 | I35: =SUM(I24,I33:I34) -> 298957.13 | J35: =SUM(J24,J33:J34) -> 327625.26 | ... L35: =SUM(L24,L33:L34) -> 385350.89
B36: Group(s) of assets classified as held for sale | C36: 6.24 | D36: 830.78 | E36: 988.8 | F36: 1005.36 | G36: 157.44 | H36: =G36 -> 157.44 | I36: =H36 -> 157.44 | J36: =I36 -> 157.44 | K36: =J36 -> 157.44 | L36: =K36 -> 157.44
B37: TOTAL ASSETS | C37: =SUM(C35:C36,C21) -> 311273.71 | D37: =SUM(D35:D36,D21) -> 320048.92 | E37: =SUM(E35:E36,E21) -> 330352.31 | F37: =SUM(F35:F36,F21) -> 340135.97 | G37: =SUM(G35:G36,G21) -> 379524.1 | H37: =SUM(H35:H36,H21) -> 406593.61 | I37: =SUM(I35:I36,I21) -> 435486.29 | J37: =SUM(J35:J36,J21) -> 465855.49 | ... L37: =SUM(L35:L36,L21) -> 528558.83
B39: Equity
B40: Equity share capital | C40: 280.91 | D40: 281.01 | E40: 281.1 | F40: 274.93 | G40: 275.04 | H40: =G40 -> 275.04 | I40: =H40 -> 275.04 | J40: =I40 -> 275.04 | K40: =J40 -> 275.04 | L40: =K40 -> 275.04
B41: Other equity | C41: 75587.62 | D41: 82126.65 | E41: 89044.85 | F41: 86084.31 | G41: 97380.56 | H41: =G41+IS!H35 -> 124450.07 | I41: =H41+IS!I35 -> 153342.75 | J41: =I41+IS!J35 -> 183711.95 | K41: =J41+IS!K35 -> 215008.43 | L41: =K41+IS!L35 -> 246415.29
B42: Equity attributable to owners of the Company | C42: =SUM(C40:C41) -> 75868.53 | D42: =SUM(D40:D41) -> 82407.66 | E42: =SUM(E40:E41) -> 89325.95 | F42: =SUM(F40:F41) -> 86359.24 | G42: =SUM(G40:G41) -> 97655.6 | H42: =SUM(H40:H41) -> 124725.11 | I42: =SUM(I40:I41) -> 153617.79 | J42: =SUM(J40:J41) -> 183986.99 | ... L42: =SUM(L40:L41) -> 246690.33
...

Sheet CFS
B1: =BS!B1 -> Particular | C1: =BS!H1 -> 46112 | D1: =BS!I1 -> 46477 | E1: =BS!J1 -> 46843 | F1: =BS!K1 -> 47208 | G1: =BS!L1 -> 47573
B2: A. Cash flow from operating activities
B3: Profit after tax (PAT) | C3: 27069.514 | D3: 28892.675 | E3: 30369.201 | F3: 31296.484 | G3: 31406.854
B4: Depreciation & amortisation | C4: 4389.1667 | D4: 4790.8513 | E4: 5247.6594 | F4: 5767.8142 | G4: 6360.8169
B5: Operating cash before WC | C5: =SUM(C3:C4) -> 31458.681 | D5: =SUM(D3:D4) -> 33683.526 | E5: =SUM(E3:E4) -> 35616.86 | F5: =SUM(F3:F4) -> 37064.299 | G5: =SUM(G3:G4) -> 37767.671
B6: Change in working capital | C6: -2940 | D6: -3370 | E6: -3890 | F6: -4510 | G6: -5210
B8: Net cash from operating activities (A) | C8: =SUM(C5:C6) -> 28518.681 | D8: =SUM(D5:D6) -> 30313.526 | E8: =SUM(E5:E6) -> 31726.86 | F8: =SUM(F5:F6) -> 32554.299 | G8: =SUM(G5:G6) -> 32557.671
B10: B. Cash flow from investing activities(CAPEX)
B11: Net | C11: -2617.7018 | D11: -3158.1202 | E11: -3779.7251 | F11: -4497.0411 | G11: -5343.6318
B13: C. Cash flow from financing activities(INT)
B14: Net | C14: -848.61087 | D14: -809.65225 | E14: -744.50636 | F14: -649.80396 | G14: -538.279
B16: Net cash (A+B+C) | C16: =SUM(C8+C11+C14) -> 25052.368 | D16: =SUM(D8+D11+D14) -> 26345.754 | E16: =SUM(E8+E11+E14) -> 27202.629 | F16: =SUM(F8+F11+F14) -> 27407.454 | G16: =SUM(G8+G11+G14) -> 26675.76
B17: Cash at beginning of the year | C17: 12187 | D17: =C19 -> 37239.368 | E17: =D19 -> 63585.122 | F17: =E19 -> 90787.751 | G17: =F19 -> 118195.2
B19: Cash and cash equivalents at end | C19: =C17+C16 -> 37239.368 | D19: =D17+D16 -> 63585.122 | E19: =E17+E16 -> 90787.751 | F19: =F17+F16 -> 118195.2 | G19: =G17+G16 -> 144870.96

Sheet NOTES 
B1: =BS!B1 -> Particular | C1: =BS!C1 -> 44286 | D1: =BS!D1 -> 44651 | E1: =BS!E1 -> 45016 | F1: =BS!F1 -> 45382 | G1: =BS!G1 -> 45747 | H1: =BS!H1 -> 46112 | I1: =BS!I1 -> 46477 | ... L1: =BS!L1 -> 47573 | M1: Growth rate
B3: Revenue from operations
B4: Construction & project related activity | C4: 97452.17 | D4: 100604.09 | E4: 116096.12 | F4: 147603.49 | G4: 174161.52 | H4: =G4*$M4+G4 -> 200285.75 | I4: =H4*$M4+H4 -> 230328.61 | J4: =I4*$M4+I4 -> 264877.9 | K4: =J4*$M4+J4 -> 304609.59 | L4: =K4*$M4+K4 -> 350301.03 | M4: 0.15
B5: Manufacturing & trading activity | C5: 3225.64 | D5: 3882.61 | E5: 4572.86 | F5: 4828.33 | G5: 5292.7 | H5: =G5*$M5+G5 -> 5998.6056 | I5: =H5*$M5+H5 -> 6798.6603 | J5: =I5*$M5+I5 -> 7705.4211 | K5: =J5*$M5+J5 -> 8733.1197 | L5: =K5*$M5+K5 -> 9897.8859 | M5: 0.13337345
B6: Engineering service fees | C6: 5649.1 | D6: 6561.8 | E6: 7982.07 | F6: 8940.19 | G6: 12686.28 | H6: =G6*$M6+G6 -> 15477.262 | I6: =H6*$M6+H6 -> 18882.259 | J6: =I6*$M6+I6 -> 23036.356 | K6: =J6*$M6+J6 -> 28104.355 | L6: =K6*$M6+K6 -> 34287.313 | M6: 0.22
B7: Software development products & services | C7: 16620.95 | D7: 25804.51 | E7: 32846.03 | F7: 35119.11 | G7: 37617.79 | H7: =G7*$M7+G7 -> 43260.459 | I7: =H7*$M7+H7 -> 49749.527 | J7: =I7*$M7+I7 -> 57211.956 | K7: =J7*$M7+J7 -> 65793.75 | L7: =K7*$M7+K7 -> 75662.812 | M7: 0.15
B8: Financing / annuity based projects | C8: 14442.06 | D8: 12630.81 | E8: 13375.96 | F8: 14074.87 | G8: 16137.89 | H8: =G8*$M8+G8 -> 16672.077 | I8: =H8*$M8+H8 -> 17223.946 | J8: =I8*$M8+I8 -> 17794.083 | K8: =J8*$M8+J8 -> 18383.092 | L8: =K8*$M8+K8 -> 18991.598 | M8: 0.033101403
B9: Property development activity | C9: 2065.94 | D9: 1264.35 | E9: 1316.14 | F9: 2804.71 | G9: 2410.45 | H9: =G9*$M9+G9 -> 2798.1711 | I9: =H9*$M9+H9 -> 3248.2573 | J9: =I9*$M9+I9 -> 3770.7398 | K9: =J9*$M9+J9 -> 4377.2637 | L9: =K9*$M9+K9 -> 5081.347 | M9: 0.1608501
B10: Fare collection & related activity | C10: 370.14 | D10: 201.39 | E10: 458.2 | F10: 602.98 | G10: 622.99 | H10: =G10*$M10+G10 -> 716.4385 | I10: =H10*$M10+H10 -> 823.90427 | J10: =I10*$M10+I10 -> 947.48992 | K10: =J10*$M10+J10 -> 1089.6134 | L10: =K10*$M10+K10 -> 1253.0554 | M10: 0.15
B11: Servicing fees | C11: 1321.35 | D11: 1345.32 | E11: 1522.46 | F11: 1871.31 | G11: 1956.96 | H11: =G11*$M11+G11 -> 2164.7489 | I11: =H11*$M11+H11 -> 2394.6006 | J11: =I11*$M11+I11 -> 2648.8579 | K11: =J11*$M11+J11 -> 2930.112 | L11: =K11*$M11+K11 -> 3241.2296 | M11: 0.10617941
B12: Commission | C12: 123.38 | D12: 129.31 | E12: 125.84 | F12: 130.37 | G12: 144.36 | H12: =G12*$M12+G12 -> 150.29811 | I12: =H12*$M12+H12 -> 156.48048 | J12: =I12*$M12+I12 -> 162.91716 | K12: =J12*$M12+J12 -> 169.6186 | L12: =K12*$M12+K12 -> 176.5957 | M12: 0.041134053
B13: Charter hire income | C13: 1.78 | D13: 2.29 | E13: 0.65
B14: Investment / portfolio management & trusteeship fees | C14: 353.25 | D14: 359.09 | E14: 217.47
B15: Fees for operation & maintenance of power plant | C15: 2682.29 | D15: 2804.94 | E15: 3147.62 | F15: 3140.33 | G15: 3177.71 | H15: =G15*$M15+G15 -> 3318.7075 | I15: =H15*$M15+H15 -> 3465.9612 | J15: =I15*$M15+I15 -> 3619.7487 | K15: =J15*$M15+J15 -> 3780.3599 | L15: =K15*$M15+K15 -> 3948.0974 | M15: 0.044370799
B16: Revenue from sale of power | D16: 81.95
B17: Total Revnue form operation | C17: =SUM(C4:C15) -> 144308.05 | D17: =SUM(D4:D16) -> 155672.46 | E17: =SUM(E4:E15) -> 181661.42 | F17: =SUM(F4:F15) -> 219115.69 | G17: =SUM(G4:G15) -> 254208.65 | H17: =SUM(H4:H15) -> 290842.51 | I17: =SUM(I4:I15) -> 333072.21 | J17: =SUM(J4:J15) -> 381775.47 | K17: =SUM(K4:K15) -> 437970.87 | L17: =SUM(L4:L15) -> 502840.96
B19: Other income
B20: Lease rentals | C20: 150.91 | D20: 87.38 | E20: 148.45 | F20: 166.11 | G20: 187.42 | H20: =G20*$M20+G20 -> 208.0362 | I20: =H20*$M20+H20 -> 230.92018 | J20: =I20*$M20+I20 -> 256.3214 | K20: =J20*$M20+J20 -> 284.51676 | L20: =K20*$M20+K20 -> 315.8136 | M20: 0.11
B21: Property maintenance recoveries | C21: 69.71 | D21: 49.63 | E21: 57.56 | F21: 86.44 | G21: 76.67 | H21: =G21*$M21+G21 -> 81.662038 | I21: =H21*$M21+H21 -> 86.979111 | J21: =I21*$M21+I21 -> 92.642383 | K21: =J21*$M21+J21 -> 98.674394 | L21: =K21*$M21+K21 -> 105.09915 | M21: 0.065110709
B22: Gain on sale of subsidiary / business | D22: 1.65 | F22: 511.73 | G22: 187.44 | H22: =G22*$M22+G22 -> 168.696 | I22: =H22*$M22+H22 -> 151.8264 | J22: =I22*$M22+I22 -> 136.64376 | K22: =J22*$M22+J22 -> 122.97938 | L22: =K22*$M22+K22 -> 110.68145 | M22: -0.1
B23: Premium on forward exchange contracts (net) | C23: 44.55 | D23: 53.65 | E23: 65.14 | F23: 28.83 | G23: 45.09 | H23: =G23*$M23+G23 -> 49.880946 | I23: =H23*$M23+H23 -> 55.180943 | J23: =I23*$M23+I23 -> 61.044081 | K23: =J23*$M23+J23 -> 67.530195 | L23: =K23*$M23+K23 -> 74.705477 | M23: 0.10625295
B24: Gain on sale of investment property | E24: 106.28 | F24: 21.93 | G24: 142.39 | H24: =G24*$M24+G24 -> 158.0529 | I24: =H24*$M24+H24 -> 175.43872 | J24: =I24*$M24+I24 -> 194.73698 | K24: =J24*$M24+J24 -> 216.15805 | L24: =K24*$M24+K24 -> 239.93543 | M24: 0.11
B25: Technical fees | C25: 0.06 | D25: 4.75 | E25: 2.82
B26: Miscellaneous income | C26: 879.08 | D26: 651.71 | E26: 1299.03 | F26: 1182.18 | G26: 886.79 | H26: =G26*$M26+G26 -> 974.3157 | I26: =H26*$M26+H26 -> 1070.4801 | J26: =I26*$M26+I26 -> 1176.1359 | K26: =J26*$M26+J26 -> 1292.2199 | L26: =K26*$M26+K26 -> 1419.7613 | M26: 0.098699463
B27: Other Operational Income | C27: =SUM(C20:C26) -> 1144.31 | D27: =SUM(D20:D26) -> 848.77 | E27: =SUM(E20:E26) -> 1679.28 | F27: =SUM(F20:F26) -> 1997.22 | G27: =SUM(G20:G26) -> 1525.8 | H27: =SUM(H20:H26) -> 1640.6438 | I27: =SUM(I20:I26) -> 1770.8255 | J27: =SUM(J20:J26) -> 1917.5246 | ... L27: =SUM(L20:L26) -> 2265.9965
A29: # | B29: Total Revnue form operation | C29: =C27+C17 -> 145452.36 | D29: =D27+D17 -> 156521.23 | E29: =E27+E17 -> 183340.7 | F29: =F27+F17 -> 221112.91 | G29: =G27+G17 -> 255734.45 | H29: =H27+H17 -> 292483.16 | I29: =I27+I17 -> 334843.03 | J29: =J27+J17 -> 383693 | ... L29: =L27+L17 -> 505106.96
B32: Other income (net) | C32: 3429.35 | D32: 2267.08 | E32: 2929.17 | F32: 4158.03 | G32: 4124.82 | H32: =$M$32*G32+G32 -> 4454.8056 | I32: =$M$32*H32+H32 -> 4811.19 | J32: =$M$32*I32+I32 -> 5196.0853 | K32: =$M$32*J32+J32 -> 5611.7721 | L32: =$M$32*K32+K32 -> 6060.7138 | M32: 0.08
B33: Manufacturing, construction and Operating Exp.
B34: Cost of raw materials & components | C34: 15562.05 | D34: 17100.84 | E34: 18995.11 | F34: 19442.25 | G34: 27655.02 | H34: =G34*(1+$M34) -> 30973.622 | I34: =H34*(1+$M34) -> 34690.457 | J34: =I34*(1+$M34) -> 38853.312 | K34: =J34*(1+$M34) -> 43515.709 | L34: =K34*(1+$M34) -> 48737.594 | M34: 0.12
B35: Construction materials consumed | C35: 24558.23 | D35: 33506.21 | E35: 43237.35 | F35: 54813.97 | G35: 63526.44 | H35: =G35*(1+$M35) -> 77502.257 | I35: =H35*(1+$M35) -> 94552.753 | J35: =I35*(1+$M35) -> 115354.36 | K35: =J35*(1+$M35) -> 140732.32 | L35: =K35*(1+$M35) -> 171693.43 | M35: 0.22
B36: Purchase of stock-in-trade | C36: 1213.58 | D36: 1069.5 | E36: 1052.86 | F36: 1063.77 | G36: 1402.14 | H36: =G36*(1+$M36) -> 1410.893 | I36: =H36*(1+$M36) -> 1419.7006 | J36: =I36*(1+$M36) -> 1428.5631 | K36: =J36*(1+$M36) -> 1437.481 | L36: =K36*(1+$M36) -> 1446.4546 | M36: 0.0062425693
B37: Stores, spares and tools consumed | C37: 2032.89 | D37: 3091.07 | E37: 4814.89 | F37: 4432.02 | G37: 4393.39 | H37: =G37*(1+$M37) -> 4478.8068 | I37: =H37*(1+$M37) -> 4565.8842 | J37: =I37*(1+$M37) -> 4654.6546 | K37: =J37*(1+$M37) -> 4745.1509 | L37: =K37*(1+$M37) -> 4837.4066 | M37: 0.019442105
B38: Sub-contracting charges | C38: 22316.18 | D38: 24772.33 | E38: 25624.45 | F38: 35054.35 | G38: 40570.92 | H38: =G38*(1+$M38) -> 46807.798 | I38: =H38*(1+$M38) -> 54003.459 | J38: =I38*(1+$M38) -> 62305.292 | K38: =J38*(1+$M38) -> 71883.347 | L38: =K38*(1+$M38) -> 82933.817 | M38: 0.1537278
B39: Changes in inventories (Finished/WIP) | C39: 343.37 | D39: -2076.6 | E39: -3156.64 | F39: 1021.07 | G39: -410.79 | H39: =G39*(1+$M39) -> -408.72682 | I39: =H39*(1+$M39) -> -406.67401 | J39: =I39*(1+$M39) -> -404.63151 | K39: =J39*(1+$M39) -> -402.59926 | L39: =K39*(1+$M39) -> -400.57722 | M39: -0.0050224596
B40: Other mfg., const. & operating expenses | C40: 12983.56 | D40: 16322.62 | E40: 20020.81 | F40: 24486.49 | G40: 27533.55 | H40: =G40*(1+$M40) -> 30562.241 | I40: =H40*(1+$M40) -> 33924.087 | J40: =I40*(1+$M40) -> 37655.737 | K40: =J40*(1+$M40) -> 41797.868 | L40: =K40*(1+$M40) -> 46395.633 | M40: 0.11
B41: Finance cost (Financial Services) | C41: 7691.04 | D41: 5952.54 | E41: 6026.44 | F41: 5714.9 | G41: 6302.23 | H41: =G41*(1+$M41) -> 6521.8839 | I41: =H41*(1+$M41) -> 6749.1935 | J41: =I41*(1+$M41) -> 6984.4256 | K41: =J41*(1+$M41) -> 7227.8564 | L41: =K41*(1+$M41) -> 7479.7715 | M41: 0.034853365
A42: # | B42: COGS | C42: =SUM(C34:C41) -> 86700.9 | D42: =SUM(D34:D41) -> 99738.51 | E42: =SUM(E34:E41) -> 116615.27 | F42: =SUM(F34:F41) -> 146028.82 | G42: =SUM(G34:G41) -> 170972.9 | H42: =SUM(H34:H41) -> 197848.77 | I42: =SUM(I34:I41) -> 229498.86 | J42: =SUM(J34:J41) -> 266831.71 | ... L42: =SUM(L34:L41) -> 363123.53
B44: Employee benefits expense | C44: 24750.54 | D44: 29733.53 | E44: 37214.11 | F44: 41171.02 | G44: 46768.68 | H44: =$M44*H$29 -> 46797.305 | I44: =$M44*I$29 -> 53574.885 | J44: =$M44*J$29 -> 61390.879 | K44: =$M44*K$29 -> 70408.472 | L44: =$M44*L$29 -> 80817.113 | M44: 0.16
B45: Sales, administration and other expenses | C45: 8903.49 | D45: 8831.89 | E45: 8758.04 | F45: 10419.42 | G45: 11558.13 | H45: =$M45*H$29 -> 8774.4948 | I45: =$M45*I$29 -> 10045.291 | J45: =$M45*J$29 -> 11510.79 | K45: =$M45*K$29 -> 13201.588 | L45: =$M45*L$29 -> 15153.209 | M45: 0.03
B47: TANGIBLES
...

Sheet DCF
C2: =BS!H1 -> 46112 | D2: =BS!I1 -> 46477 | E2: =BS!J1 -> 46843 | F2: =BS!K1 -> 47208 | G2: =BS!L1 -> 47573 | H2: TV
C3: 1 | D3: 2 | E3: 3 | F3: 4 | G3: 5
B4: EBIT | C4: =IS!H26 -> 39128.222 | D4: =IS!I26 -> 41744.335 | E4: =IS!J26 -> 43908.042 | F4: =IS!K26 -> 45349.715 | G4: =IS!L26 -> 45713.003
B5: NOPAT | C5: =C4*(1-25%) -> 29346.167 | D5: =D4*(1-25%) -> 31308.251 | E5: =E4*(1-25%) -> 32931.031 | F5: =F4*(1-25%) -> 34012.286 | G5: =G4*(1-25%) -> 34284.752
B6: D&A | C6: =IS!H25 -> 4389.1667 | D6: =IS!I25 -> 4790.8513 | E6: =IS!J25 -> 5247.6594 | F6: =IS!K25 -> 5767.8142 | G6: =IS!L25 -> 6360.8169
B7: CHANGE IN WC | C7: =CFS!C6 -> -2940 | D7: =CFS!D6 -> -3370 | E7: =CFS!E6 -> -3890 | F7: =CFS!F6 -> -4510 | G7: =CFS!G6 -> -5210
B8: CAPEX | C8: =-'NOTES '!H81 -> -5279.4079 | D8: =-'NOTES '!I81 -> -6044.0162 | E8: =-'NOTES '!J81 -> -6925.7726 | F8: =-'NOTES '!K81 -> -7943.0864 | G8: =-'NOTES '!L81 -> -9117.3306
B10: FCFF | C10: =SUM(C5:C8) -> 25515.926 | D10: =SUM(D5:D8) -> 26685.086 | E10: =SUM(E5:E8) -> 27362.918 | F10: =SUM(F5:F8) -> 27327.014 | G10: =SUM(G5:G8) -> 26318.239 | H10: =G10*(1+G15)/(G16-G15) -> 518553.94
B12: PV | C12: =PV($G$16,C3,,-C10,0) -> 22908.928 | D12: =PV($G$16,D3,,-D10,0) -> 21510.747 | E12: =PV($G$16,E3,,-E10,0) -> 19803.535 | F12: =PV($G$16,F3,,-F10,0) -> 17756.851 | G12: =PV($G$16,G3,,-G10,0) -> 15354.088 | H12: =PV($G$16,G3,,-H10,0) -> 302524.91
B15: EV | C15: =SUM(G16,C12:H12) -> 399859.17 | E15: Terminal Growth | G15: 0.06
B16: DEBT | C16: =BS!G49+BS!G60 -> 93364.64 | E16: WACC | G16: =WACC!D21 -> 0.11379832
B17: CASH | C17: =BS!G28 -> 12187
B18: Equity value | C18: =C15-C16+C17 -> 318681.53 | E18: Sensitivity Analysis- Value per Share
B19: intrinsic value | C19: =C18/IS!L38*10000000 -> 2317.36
G20: WACC
E21: Terminal Growth | F21: =C19 -> 2317.36 | G21: 0.1 | H21: 0.1138 | I21: 0.12 | J21: 0.13
F22: 0.05 | G22: 2638.247 | H22: 1954.9775 | I22: 1735.4647 | J22: 1452.842
F23: 0.06 | G23: 3291.8178 | H23: 2317.2719 | I23: 2025.047 | J23: 1662.4422
F24: 0.07 | G24: 4381.1026 | H24: 2844.9976 | I24: 2430.4623 | J24: 1941.9091
F25: 0.08 | G25: 6559.6723 | H25: 3684.9869 | I25: 3038.5852 | J25: 2333.1627
F27: Current Share Price | J27: 1561.01
F29: Discount/Premium | J29: =J27/C19 -> 0.67361567

Sheet DDM
B1: Dividend Discount Model (DDM)
B3: Single-Stage Model Assumptions
B4: Dividends Per Share (DPS) – Current Period | C4: 34
B5: Cost of Equity (Ke) | C5: 0.126
B6: Dividend Payout % | C6: 0.31
B7: ROE | C7: 0.166
B8: Rentention ratio | C8: =1-C6 -> 0.69
B9: Growth Rate | C9: =C7*C8 -> 0.11454
B11: Calculation of D1 | C11: =C4*(1+C9) -> 37.89436
B12: Value Per Share | C12: =C11/(C5-C9) -> 3306.6632
B14: Two-Stage Model Assumptions
C16: Stage 1 | D16: Stage 2
B17: Dividend Growth Rate (g): | C17: 0.1145 | D17: 0.06
F18: Stage 1
E19: =BS!G1 -> 45747 | F19: =BS!H1 -> 46112 | G19: =BS!I1 -> 46477 | H19: =BS!J1 -> 46843 | I19: =BS!K1 -> 47208 | J19: =BS!L1 -> 47573
B20: Stage 1 Dividends | E20: 0 | F20: 1 | G20: 2 | H20: 3 | I20: 4 | J20: 5
B21: Dividends Per Share (DPS) | E21: =C4 -> 34 | F21: =E21*(1+$C$17) -> 37.893 | G21: =F21*(1+$C$17) -> 42.231749 | H21: =G21*(1+$C$17) -> 47.067284 | I21: =H21*(1+$C$17) -> 52.456488 | J21: =I21*(1+$C$17) -> 58.462756
B22: Cost of Equity (Ke) | E22: =$C$5 -> 0.126 | F22: =$C$5 -> 0.126 | G22: =$C$5 -> 0.126 | H22: =$C$5 -> 0.126 | I22: =$C$5 -> 0.126 | J22: =$C$5 -> 0.126
B23: Present Value (PV) of Dividend | E23: =PV(E22,E20,,-E21,0) -> 34 | F23: =PV(F22,F20,,-F21,0) -> 33.652753 | G23: =PV(G22,G20,,-G21,0) -> 33.309053 | H23: =PV(H22,H20,,-H21,0) -> 32.968863 | I23: =PV(I22,I20,,-I21,0) -> 32.632147 | J23: =PV(J22,J20,,-J21,0) -> 32.29887
B25: Share Price Calculation
B26: PV of Sum of Stage 1 Dividends | D26: =SUM(F23:J23) -> 164.86169
B27: Year 5 Dividend × (1 + Stage 2 Growth Rate) | D27: =+J21*(1+D17) -> 61.970521
B28: Stage 2 Terminal Value | D28: =+D27/(C5-D17) -> 938.94729
B29: PV of Stage 2 Terminal Value | D29: =PV(C5,J20,,-D28,0) -> 518.73943
B30: Value Per Share | D30: =SUM(D26,D29) -> 683.60111
B32: Three-Stage Model Assumptions
C34: Stage 1 | D34: Stage 2 | E34: Stage 3
B35: Dividend Growth Rate (g): | C35: 0.1145 | D35: 0.07 | E35: 0.04
D37: Stage 1 | H37: Stage 2 | L37: Stage 3
C38: =BS!G1 -> 45747 | D38: =BS!H1 -> 46112 | E38: =BS!I1 -> 46477 | F38: =BS!J1 -> 46843 | G38: =BS!K1 -> 47208 | H38: =BS!L1 -> 47573 | I38: =EDATE(H38,12) -> 47938 | J38: =EDATE(I38,12) -> 48304 | K38: =EDATE(J38,12) -> 48669 | L38: =EDATE(K38,12) -> 49034
B39: Stage 1 Dividends | C39: 0 | D39: 1 | E39: 2 | F39: 3 | G39: 4 | H39: 5 | I39: 6 | J39: 7 | K39: 8 | L39: 9
B40: Dividends Per Share (DPS) | C40: =C4 -> 34 | D40: =C40*(1+$C$35) -> 37.893 | E40: =D40*(1+$C$35) -> 42.231749 | F40: =E40*(1+$C$35) -> 47.067284 | G40: =F40*(1+$C$35) -> 52.456488 | H40: =G40*(1+$D$35) -> 56.128442 | I40: =H40*(1+$D$35) -> 60.057433 | J40: =I40*(1+$D$35) -> 64.261453 | K40: =J40*(1+$D$35) -> 68.759755 | L40: =K40*(1+E35)/(L41-E35) -> 831.51331
B41: Cost of Equity (Ke) | C41: =$C$5 -> 0.126 | D41: =$C$5 -> 0.126 | E41: =$C$5 -> 0.126 | F41: =$C$5 -> 0.126 | G41: =$C$5 -> 0.126 | H41: =$C$5 -> 0.126 | I41: =$C$5 -> 0.126 | J41: =$C$5 -> 0.126 | ... L41: =$C$5 -> 0.126
B42: Present Value (PV) of Dividend | C42: =PV(C41,C39,,-C40,0) -> 34 | D42: =PV(D41,D39,,-D40,0) -> 33.652753 | E42: =PV(E41,E39,,-E40,0) -> 33.309053 | F42: =PV(F41,F39,,-F40,0) -> 32.968863 | G42: =PV(G41,G39,,-G40,0) -> 32.632147 | H42: =PV(H41,H39,,-H40,0) -> 31.009234 | I42: =PV(I41,I39,,-I40,0) -> 29.467034 | J42: =PV(J41,J39,,-J40,0) -> 28.001533 | ... L42: =PV(L41,L39,,-L40,0) -> 285.77464
B44: Share Price Calculation
B45: Value Per Share | D45: =SUM(C42:L42) -> 567.42418

Sheet RELATIVE VALUATION 
B2: Company | C2: CMP | D2: Equity Value | E2: Debt | F2: Enterprise Value | G2: EPS | H2: Book Value | I2: Revenue | J2: Net Income | K2: EBITDA | L2: P/E | M2: P/B | N2: P/S | O2: EV/EBITDA | P2: EV/Sales | R2: No of shares
B3: Larsen & Toubro | C3: 4081.95 | D3: 330645.48 | E3: =DCF!C16 -> 93364.64 | F3: 411823.12 | G3: 128.61759 | H3: 737.04 | I3: 270722.51 | J3: 17687.39 | K3: 26438.38 | R3: 137.47
B4: Hind.Aeronautics | C4: 4302.8 | D4: 284992 | E4: 11.4 | F4: 243300.41 | G4: 126.64 | H4: 554.96 | I4: 32104.78 | J4: 8364.05 | K4: 12170 | L4: =C4/G4 -> 33.976627 | M4: =C4/H4 -> 7.7533516 | N4: =C4/(I4/R4) -> 8.9635021 | O4: =F4/K4 -> 19.991817 | P4: =F4/I4 -> 7.5783235 | R4: 66.88
B5: Bharat Electron | C5: 391.35 | D5: 283619 | E5: 58.89 | F5: 278010.56 | G5: 7.79 | H5: 29.5 | I5: 25152.11 | J5: 5322.68 | K5: 7400 | L5: =C5/G5 -> 50.237484 | M5: =C5/H5 -> 13.266102 | N5: =C5/(I5/R5) -> 11.37356 | O5: =F5/K5 -> 37.568995 | P5: =F5/I5 -> 11.05317 | R5: 730.98
B6: Cummins India | C6: 4357 | D6: 124500 | E6: 24.35 | F6: 119039.92 | G6: 83.48 | H6: 284.81 | I6: 11643.62 | J6: 1999.94 | K6: 3028 | L6: =C6/G6 -> 52.192142 | M6: =C6/H6 -> 15.297918 | N6: =C6/(I6/R6) -> 10.372723 | O6: =F6/K6 -> 39.313052 | P6: =F6/I6 -> 10.223618 | R6: 27.72
B7: Polycab India | C7: 7360 | D7: 106800 | E7: 223.12 | F7: 109920.55 | G7: 163.6 | H7: 703.75 | I7: 24595.05 | J7: 2045.54 | K7: 1488 | L7: =C7/G7 -> 44.987775 | M7: =C7/H7 -> 10.458259 | N7: =C7/(I7/R7) -> 4.494693 | O7: =F7/K7 -> 73.871337 | P7: =F7/I7 -> 4.4692143 | R7: 15.02
B8: Siemens | C8: 3091.55 | D8: 112580 | E8: 145.3 | F8: 103567.13 | G8: 59.09 | H8: 371.46 | I8: 17364.2 | J8: 2105.9 | K8: 2478 | L8: =C8/G8 -> 52.319343 | M8: =C8/H8 -> 8.3226996 | N8: =C8/(I8/R8) -> 6.3400615 | O8: =F8/K8 -> 41.794645 | P8: =F8/I8 -> 5.9644055 | R8: 35.61
B9: A B B | C9: 5140.2 | D9: 108000 | E9: 73.22 | F9: 103736.54 | G9: 83.24 | H9: 339.52 | I9: 13010.65 | J9: 1871.64 | K9: 2212 | L9: =C9/G9 -> 61.751562 | M9: =C9/H9 -> 15.139609 | N9: =C9/(I9/R9) -> 8.3716677 | O9: =F9/K9 -> 46.89717 | P9: =F9/I9 -> 7.973202 | R9: 21.19
B10: CG Power & Ind | C10: 668.1 | D10: 105900 | E10: 116.82 | F10: 104729.43 | G10: 6.93 | H10: 47.38 | I10: 11069.29 | J10: 972.98 | K10: 1771 | L10: =C10/G10 -> 96.406926 | M10: =C10/H10 -> 14.100886 | N10: =C10/(I10/R10) -> 9.2181985 | O10: =F10/K10 -> 59.135759 | P10: =F10/I10 -> 9.4612599 | R10: 152.73
B11: Ashok Leyland | C11: 173.4 | D11: 98500 | E11: 54513.09 | F11: 151294.48 | G11: 5.55 | H11: 21.42 | I11: 50976.16 | J11: 3382.79 | K11: 4648 | L11: =C11/G11 -> 31.243243 | M11: =C11/H11 -> 8.0952381 | N11: =C11/(I11/R11) -> 1.9976518 | O11: =F11/K11 -> 32.550448 | P11: =F11/I11 -> 2.9679458 | R11: 587.27
B13: Average | L13: =AVERAGE(L4:L11) -> 52.889388 | M13: =AVERAGE(M4:M11) -> 11.554258 | N13: =AVERAGE(N4:N11) -> 7.6415071 | O13: =AVERAGE(O4:O11) -> 43.890403 | P13: =AVERAGE(P4:P11) -> 7.4613924
B14: Median | L14: =MEDIAN(L4:L11) -> 51.214813 | M14: =MEDIAN(M4:M11) -> 11.862181 | N14: =MEDIAN(N4:N11) -> 8.6675849 | O14: =MEDIAN(O4:O11) -> 40.553848 | P14: =MEDIAN(P4:P11) -> 7.7757627
L16: =L2 -> P/E | M16: =M2 -> P/B | N16: =N2 -> P/S | O16: =O2 -> EV/EBITDA | P16: =P2 -> EV/Sales
B18: Enterprise Value | O18: =O14*K3 -> 1072178 | P18: =P14*I3 -> 2105074
B19: (-) Debt | O19: =-DCF!C16 -> -93364.64 | P19: =O19 -> -93364.64
B20: (+) Cash | O20: =DCF!C17 -> 12187 | P20: =O20 -> 12187
B21: Equity Value | O21: =SUM(O18:O20) -> 991000.41 | P21: =SUM(P18:P20) -> 2023896.4
B22: No of Shares | O22: =R3 -> 137.47 | P22: =R3 -> 137.47
B23: Fair Value - Different Multiples | L23: =L14*G3 -> 6587.1257 | M23: =M14*H3 -> 8742.9015 | N23: =(I3/R3)*N14 -> 17069.254 | O23: =O21/O22 -> 7208.8485 | P23: =P21/P22 -> 14722.458
B25: Weightage % | L25: =S28 -> 0.2 | M25: =S29 -> 0.15 | N25: =S30 -> 0.1 | O25: =S26 -> 0.35 | P25: =S27 -> 0.2 | R25: Multiple | S25: Weight (%)
B26: Combined Valuation | C26: =(L25*L23)+(M25*M23)+(N25*N23)+(O25*O23)+(P25*P23) -> 9803.3745 | R26: EV / EBITDA | S26: 0.35 | T26: Best operating metric, capital-structure neutral
B27: CMP | C27: =C3 -> 4081.95 | R27: EV / Sales | S27: 0.2 | T27: Strong order book, revenue visibility
C28: =C26/C27 -> 2.40164 | R28: P/E | S28: 0.2 | T28: Mature profitability but earnings volatility
R29: P/B | S29: 0.15 | T29: Asset-heavy but weak economic signal
R30: P/S | S30: 0.1 | T30: Least reliable for EPC

Sheet WACC
B2: WACC Calculator
B4: WACC Calculation | F4: Comparable Companies Unlevered Beta
B5: Capital Structure | F5: Company | G5: Levered Beta | H5: Debt | I5: Equity | J5: Debt/Equity | K5: Tax Rate | L5: Unlevered Beta
B6: Debt to Total Capitalization | D6: 0.19298954 | F6: ='RELATIVE VALUATION '!B3 -> Larsen & Toubro | G6: 1.05 | H6: =DCF!C16 -> 93364.64 | I6: 560342.87 | J6: =H6/I6 -> 0.16662056 | K6: 0.24986015 | L6: =G6/((1+(1-K6)*J6)) -> 0.93334269
B7: Equity to Total Capitalization | D7: 0.80701046 | F7: ='RELATIVE VALUATION '!B4 -> Hind.Aeronautics | G7: 0.87 | H7: 11.4 | I7: 287927.7 | J7: =H7/I7 -> 3.9593273e-05 | K7: 0.23034417 | L7: =G7/((1+(1-K7)*J7)) -> 0.86997349
B8: Debt / Equity | D8: =D6/D7 -> 0.23914131 | F8: ='RELATIVE VALUATION '!B5 -> Bharat Electron | G8: 0.85 | H8: 58.89 | I8: 287164.66 | J8: =H8/I8 -> 0.00020507398 | K8: 0.25522609 | L8: =G8/((1+(1-K8)*J8)) -> 0.8498702
F9: ='RELATIVE VALUATION '!B6 -> Cummins India | G9: 1.58 | H9: 24.35 | I9: 145212.74 | J9: =H9/I9 -> 0.00016768501 | K9: 0.22865925 | L9: =G9/((1+(1-K9)*J9)) -> 1.5797957
B10: Cost of Equity Calculation | F10: ='RELATIVE VALUATION '!B7 -> Polycab India | G10: 0.87 | H10: 223.12 | I10: 122256.29 | J10: =H10/I10 -> 0.0018250186 | K10: 0.24263102 | L10: =G10/((1+(1-K10)*J10)) -> 0.86879914
B11: Risk Free Rate | D11: 0.066 | F11: ='RELATIVE VALUATION '!B8 -> Siemens | G11: 0.86 | H11: 145.3 | I11: 111985.57 | J11: =H11/I11 -> 0.0012974886 | K11: 0.21974805 | L11: =G11/((1+(1-K11)*J11)) -> 0.85913024
B12: Equity Risk Premium | D12: 0.06 | F12: ='RELATIVE VALUATION '!B9 -> A B B | G12: 0.86 | H12: 73.22 | I12: 110810.46 | J12: =H12/I12 -> 0.00066076795 | K12: 0.25441284 | L12: =G12/((1+(1-K12)*J12)) -> 0.85957652
B13: Levered Beta | D13: =L15*(1+(1-D18)*D8) -> 1.0260084 | F13: ='RELATIVE VALUATION '!B10 -> CG Power & Ind | G13: 0.97 | H13: 116.82 | I13: 109704.97 | J13: =H13/I13 -> 0.001064856 | K13: 0.27818868 | L13: 0.96925501
B14: Cost of Equity | D14: =D11+D12*D13 -> 0.12756051 | F14: ='RELATIVE VALUATION '!B11 -> Ashok Leyland | G14: 1.99 | H14: 54513.09 | I14: 105767.44 | J14: =H14/I14 -> 0.51540521 | K14: 0.26402369 | L14: 1.4427336
F15: Median | G15: =MEDIAN(G6:G14) -> 0.87 | J15: =MEDIAN(J6:J14) -> 0.001064856 | L15: =MEDIAN(L6:L14) -> 0.86997349
B16: Cost of Debt Calculation
B17: Cost of Debt | D17: 0.075
B18: Tax Rate | D18: 0.25
B19: After-Tax Cost of Debt | D19: =D17*(1-D18) -> 0.05625
B21: WACC | D21: =(D14*D7)+(D19*D6) -> 0.11379832
