Workbook

Sheet INDEX
C10: Incorporated in 1997, LG Electronics India Limited is a manufacturer and distributor of home appliances and consumer electronics.
D15: 1 | E15: INCOME STATEMENT | H15: MODEL
D17: 2 | E17: BALANCE SHEET
D19: 3 | E19: CASH FLOW STATEMENT
D21: 4 | E21: DISCOUNT CASH FLOW
D23: 5 | E23: WACC
D25: 6 | E25: WORKING NOTES 1 | H25: NOTES
D27: 7 | E27: WORKING NOTES 2
D29: 8 | E29: DCF | H29: ROUGH DCF
C32: Business Profile
C33: LG Electronics India Ltd (LGEIL) is a leading player in India’s home appliances and consumer electronics industry, holding the #1 market share across multiple key categories such as washing machines, refrigerators, panel televisions, inverter air conditioners, and microwaves in the offline channel.
C39: Market Leadership
C40: It has a 78% Market share in the Indian home appliances and consumer electronics market (excluding mobile phones) in 2024 and 77% in H1FY25.

Sheet P&L
B1: Particulars | C1: 44652 | D1: =EDATE(C1,12) -> 45017 | E1: =EDATE(D1,12) -> 45383 | F1: =EDATE(E1,12) -> 45748 | G1: =EDATE(F1,12) -> 46113 | H1: =EDATE(G1,12) -> 46478 | I1: =EDATE(H1,12) -> 46844 | J1: =EDATE(I1,12) -> 47209 | K1: =EDATE(J1,12) -> 47574
B2: Income
B3: Revenue from operations | C3: 168342 | D3: 198646 | E3: 213520 | F3: 243666.38 | G3: =SUM('rP&L'!H3,'rP&L'!H5,'rP&L'!H7,'rP&L'!H9,'rP&L'!H11) -> 265983.6 | H3: =SUM('rP&L'!I3,'rP&L'!I5,'rP&L'!I7,'rP&L'!I9,'rP&L'!I11) -> 290355.35 | I3: =SUM('rP&L'!J3,'rP&L'!J5,'rP&L'!J7,'rP&L'!J9,'rP&L'!J11) -> 316972.01 | J3: =SUM('rP&L'!K3,'rP&L'!K5,'rP&L'!K7,'rP&L'!K9,'rP&L'!K11) -> 346041.75 | K3: =SUM('rP&L'!L3,'rP&L'!L5,'rP&L'!L7,'rP&L'!L9,'rP&L'!L11) -> 377792.19
A5: # | B5: SALES | C5: =SUM(C3) -> 168342 | D5: =SUM(D3) -> 198646 | E5: =SUM(E3) -> 213520 | F5: =SUM(F3) -> 243666.38 | G5: =SUM(G3) -> 265983.6 | H5: =SUM(H3) -> 290355.35 | I5: =SUM(I3) -> 316972.01 | J5: =SUM(J3) -> 346041.75 | K5: =SUM(K3) -> 377792.19
B7: Cost of materials consumed | C7: 100322 | D7: 123608 | E7: 129160.49 | F7: 147405.5
B8: Purchases of stock-in-trade | C8: 14917 | D8: 18788 | E8: 19357.72 | F8: 19729.36
B9: Changes in inventories of finished goods, stock-in-trade and work-in-progress | C9: 2766 | D9: -2115 | E9: 783.57 | F9: -1333.98
B10: COGS | C10: =SUM(C7:C9) -> 118005 | D10: =SUM(D7:D9) -> 140281 | E10: =SUM(E7:E9) -> 149301.78 | F10: =SUM(F7:F9) -> 165800.88 | G10: ='rP&L'!$H$17*'P&L'!G3 -> 185314.23 | H10: ='rP&L'!$H$17*'P&L'!H3 -> 202294.35 | I10: ='rP&L'!$H$17*'P&L'!I3 -> 220838.52 | J10: ='rP&L'!$H$17*'P&L'!J3 -> 241091.79 | K10: ='rP&L'!$H$17*'P&L'!K3 -> 263212.73
A11: # | B11: GROSS PROFIT | C11: =C5-C10 -> 50337 | D11: =D5-D10 -> 58365 | E11: =E5-E10 -> 64218.22 | F11: =F5-F10 -> 77865.5 | G11: =G5-G10 -> 80669.366 | H11: =H5-H10 -> 88061.001 | I11: =I5-I10 -> 96133.489 | J11: =J5-J10 -> 104949.96 | K11: =K5-K10 -> 114579.46
B13: Employee benefits expense | C13: 7255 | D13: 7992 | E13: 8868.24 | F13: 9627.94
B14: Other expenses | C14: 25995 | D14: 31380 | E14: 33101.25 | F14: 37136.32
B15: TOTAL EXPENSES | C15: =SUM(C13:C14) -> 33250 | D15: =SUM(D13:D14) -> 39372 | E15: =SUM(E13:E14) -> 41969.49 | F15: =SUM(F13:F14) -> 46764.26 | G15: ='rP&L'!$H$19*'P&L'!G3 -> 52145.793 | H15: ='rP&L'!$H$19*'P&L'!H3 -> 56923.848 | I15: ='rP&L'!$H$19*'P&L'!I3 -> 62142.016 | J15: ='rP&L'!$H$19*'P&L'!J3 -> 67841.106 | K15: ='rP&L'!$H$19*'P&L'!K3 -> 74065.745
B16: EBITDA | C16: =C11-C15 -> 17087 | D16: =D11-D15 -> 18993 | E16: =E11-E15 -> 22248.73 | F16: =F11-F15 -> 31101.24 | G16: =G11-G15 -> 28523.573 | H16: =H11-H15 -> 31137.153 | I16: =I11-I15 -> 33991.474 | J16: =J11-J15 -> 37108.857 | K16: =K11-K15 -> 40513.714
B18: Depreciation and amortisation expense | C18: 2584 | D18: 3004 | E18: 3643.69 | F18: 3803.57 | G18: =rBS!H26 -> 4305.2535 | H18: =rBS!I26 -> 4933.7589 | I18: =rBS!J26 -> 5619.8667 | J18: =rBS!K26 -> 6368.8844 | K18: =rBS!L26 -> 7186.6116
B19: EBIT | C19: =C16-C18 -> 14503 | D19: =D16-D18 -> 15989 | E19: =E16-E18 -> 18605.04 | F19: =F16-F18 -> 27297.67 | G19: =G16-G18 -> 24218.32 | H19: =H16-H18 -> 26203.394 | I19: =I16-I18 -> 28371.607 | J19: =J16-J18 -> 30739.972 | K19: =K16-K18 -> 33327.102
B21: Other income | C21: 2038 | D21: 2440 | E21: 2051.18 | F21: 2639.9 | G21: ='rP&L'!H14 -> 2816.3284 | H21: ='rP&L'!I14 -> 3004.5478 | I21: ='rP&L'!J14 -> 3205.3462 | J21: ='rP&L'!K14 -> 3419.5643 | K21: ='rP&L'!L14 -> 3648.0988
A22: # | B22: Finance costs( Interest) | C22: 225 | D22: 226 | E22: 285.05 | F22: 306.46 | G22: ='rP&L'!$H$21*rBS!H40 -> 313.41851 | H22: ='rP&L'!$H$21*rBS!I40 -> 313.41851 | I22: ='rP&L'!$H$21*rBS!J40 -> 313.41851 | J22: ='rP&L'!$H$21*rBS!K40 -> 313.41851 | K22: ='rP&L'!$H$21*rBS!L40 -> 313.41851
B23: Profit before tax | C23: =C19-C22+C21 -> 16316 | D23: =D19-D22+D21 -> 18203 | E23: =E19-E22+E21 -> 20371.17 | F23: =F19-F22+F21 -> 29631.11 | G23: =G19-G22+G21 -> 26721.23 | H23: =H19-H22+H21 -> 28894.524 | I23: =I19-I22+I21 -> 31263.535 | J23: =J19-J22+J21 -> 33846.118 | K23: =K19-K22+K21 -> 36661.782
A24: #
B25: Tax expense
B26: Current tax | C26: 4108 | D26: 4794 | E26: 5567.39 | F26: 7900.87
B27: Current tax expense relating to previous year | C27: 5 | D27: 14 | E27: 40.08 | F27: -1.06
B28: Deferred tax | C28: 147 | D28: -85 | E28: -346.98 | F28: -302.18
B29: Total tax expense | C29: =SUM(C26:C28) -> 4260 | D29: =SUM(D26:D28) -> 4723 | E29: =SUM(E26:E28) -> 5260.49 | F29: =SUM(F26:F28) -> 7597.63 | G29: =G23*'rP&L'!$H$23 -> 6680.3074 | H29: =H23*'rP&L'!$H$23 -> 7223.6309 | I29: =I23*'rP&L'!$H$23 -> 7815.8836 | J29: =J23*'rP&L'!$H$23 -> 8461.5296 | K29: =K23*'rP&L'!$H$23 -> 9165.4456
A30: #
B31: Profit for the year from continuing operations | C31: =C23-C29 -> 12056 | D31: =D23-D29 -> 13480 | E31: =E23-E29 -> 15110.68 | F31: =F23-F29 -> 22033.48 | G31: =G23-G29 -> 20040.922 | H31: =H23-H29 -> 21670.893 | I31: =I23-I29 -> 23447.651 | J31: =J23-J29 -> 25384.589 | K31: =K23-K29 -> 27496.337
A32: #
B33: Discontinued Operations
B34: Loss from Discontinued Operations before tax | C34: -418 | D34: -42
B35: Tax expenses of Discontinued Operations | C35: -109 | D35: -11
B36: Loss after tax from Discontinued Operations | C36: -309 | D36: -31
B38: Profit for the year from | C38: =SUM(C31,C36) -> 11747 | D38: =SUM(D31,D36) -> 13449 | E38: =SUM(E31,E34:E36) -> 15110.68 | F38: =SUM(F31,F34:F36) -> 22033.48 | G38: =SUM(G31,G34:G36) -> 20040.922 | H38: =SUM(H31,H34:H36) -> 21670.893 | I38: =SUM(I31,I34:I36) -> 23447.651 | J38: =SUM(J31,J34:J36) -> 25384.589 | K38: =SUM(K31,K34:K36) -> 27496.337
B40: Other Comprehensive Income
B41: Items that will not be reclassified to profit or loss
B42: Remeasurement of post-employment benefit obligation | C42: 28 | D42: -8 | E42: -29.98 | F42: -72.48
B43: Income tax relating to these items | C43: -7 | D43: 2 | E43: 8.13 | F43: 18.24
B44: Other Comprehensive Income for the year (net of tax) | C44: =SUM(C42:C43) -> 21 | D44: =SUM(D42:D43) -> -6 | E44: =SUM(E42:E43) -> -21.85 | F44: =SUM(F42:F43) -> -54.24
B46: Total Comprehensive Income for the year | C46: =C38+C44 -> 11768 | D46: =D38+D44 -> 13443 | E46: =E31+E44 -> 15088.83 | F46: =F31+F44 -> 21979.24 | G46: =G31+G44 -> 20040.922 | H46: =H31+H44 -> 21670.893 | I46: =I31+I44 -> 23447.651 | J46: =J31+J44 -> 25384.589 | K46: =K31+K44 -> 27496.337
A47: #
B48: Earnings per equity share from operations attributable to the equity holders of the Company
...

Sheet BS
B1: Particulars | C1: ='P&L'!C1 -> 44652 | D1: =EDATE(C1,12) -> 45017 | E1: =EDATE(D1,12) -> 45383 | F1: =EDATE(E1,12) -> 45748 | G1: =EDATE(F1,12) -> 46113 | H1: =EDATE(G1,12) -> 46478 | I1: =EDATE(H1,12) -> 46844 | J1: =EDATE(I1,12) -> 47209 | K1: =EDATE(J1,12) -> 47574
B2: Non-current assets
B3: Property, plant and equipment | C3: 10387 | D3: 13328 | E3: 13105.43 | F3: 13196.7 | G3: =rBS!H7 -> 14260.687 | H3: =rBS!I7 -> 15189.428 | I3: =rBS!J7 -> 15970.751 | J3: =rBS!K7 -> 16591.393 | K3: =rBS!L7 -> 17036.893
B4: Capital work-in-progress | C4: 1024 | D4: 243 | E4: 242.05 | F4: 753.12 | G4: =rBS!$H$29*BS!G3 -> 445.74415 | H4: =rBS!$H$29*BS!H3 -> 474.77366 | I4: =rBS!$H$29*BS!I3 -> 499.19537 | J4: =rBS!$H$29*BS!J3 -> 518.59467 | K4: =rBS!$H$29*BS!K3 -> 532.51961
B5: Intangible assets | C5: 88 | D5: 99 | E5: 83.06 | F5: 94.39 | G5: =rBS!H15 -> 96.919201 | H5: =rBS!I15 -> 98.398126 | I5: =rBS!J15 -> 98.732721 | J5: =rBS!K15 -> 97.820523 | K5: =rBS!L15 -> 95.549911
B6: Intangible assets under development | C6: 6 | D6: 3 | E6: 2.49 | F6: 0 | G6: =G5*rBS!$H$32 -> 1.9474737 | H6: =H5*rBS!$H$32 -> 1.9771909 | I6: =I5*rBS!$H$32 -> 1.9839142 | J6: =J5*rBS!$H$32 -> 1.9655847 | K6: =K5*rBS!$H$32 -> 1.9199595
B7: Financial assets
B8: (i) Trade receivables
B9: (ii) Loans | C9: 58 | D9: 48 | E9: 54.93 | F9: 56.03 | G9: =F9 -> 56.03 | H9: =G9 -> 56.03 | I9: =H9 -> 56.03 | J9: =I9 -> 56.03 | K9: =J9 -> 56.03
B10: (iii) Other financial assets | C10: 1011 | D10: 1193 | E10: 1141.05 | F10: 1265.59 | G10: =F10 -> 1265.59 | H10: =G10 -> 1265.59 | I10: =H10 -> 1265.59 | J10: =I10 -> 1265.59 | K10: =J10 -> 1265.59
B11: Deferred tax assets (net) | C11: 1278 | D11: 1365 | E11: 1719.71 | F11: 2040.13 | G11: =F11 -> 2040.13 | H11: =G11 -> 2040.13 | I11: =H11 -> 2040.13 | J11: =I11 -> 2040.13 | K11: =J11 -> 2040.13
B12: Other non-current assets | C12: 2437 | D12: 2001 | E12: 2051.54 | F12: 2357.17 | G12: =F12 -> 2357.17 | H12: =G12 -> 2357.17 | I12: =H12 -> 2357.17 | J12: =I12 -> 2357.17 | K12: =J12 -> 2357.17
A13: # | B13: Total non-current assets | C13: =SUM(C3:C12) -> 16289 | D13: =SUM(D3:D12) -> 18280 | E13: =SUM(E3:E12) -> 18400.26 | F13: =SUM(F3:F12) -> 19763.13 | G13: =SUM(G3:G12) -> 20524.218 | H13: =SUM(H3:H12) -> 21483.497 | I13: =SUM(I3:I12) -> 22289.583 | J13: =SUM(J3:J12) -> 22928.694 | K13: =SUM(K3:K12) -> 23385.803
B15: Current assets
B16: (a) Inventories | C16: 24094 | D16: 26410 | E16: 23974.18 | F16: 30314.55 | G16: =rBS!$H$35*'P&L'!G3 -> 32772.802 | H16: =rBS!$H$35*'P&L'!H3 -> 35775.733 | I16: =rBS!$H$35*'P&L'!I3 -> 39055.269 | J16: =rBS!$H$35*'P&L'!J3 -> 42637.057 | K16: =rBS!$H$35*'P&L'!K3 -> 46549.144
B17: (b) Financial assets
B18: (i) Trade receivables | C18: 13811 | D18: 14995 | E18: 17970.21 | F18: 23611.71 | G18: =rBS!$H$42*'P&L'!G3/365*2-BS!F18 -> 20914.795 | H18: =rBS!$H$42*'P&L'!H3/365*2-BS!G18 -> 27691.619 | I18: =rBS!$H$42*'P&L'!I3/365*2-BS!H18 -> 25370.51 | J18: =rBS!$H$42*'P&L'!J3/365*2-BS!I18 -> 32557.987 | K18: =rBS!$H$42*'P&L'!K3/365*2-BS!J18 -> 30685.636
B19: (ii) Cash and cash equivalents | C19: =CFS!C61 -> 37094 | D19: =CFS!D61 -> 27626 | E19: =CFS!E61 -> 22226.05 | F19: =CFS!F61 -> 37414.73 | G19: =CFS!G61 -> 62699.529 | H19: =CFS!H61 -> 73680.127 | I19: =CFS!I61 -> 102727.78 | J19: =CFS!J61 -> 117435.96 | K19: =CFS!K61 -> 150546.59
B20: (iii) Loans | C20: 21 | D20: 21 | E20: 18.17 | F20: 30.65 | G20: =F20 -> 30.65 | H20: =G20 -> 30.65 | I20: =H20 -> 30.65 | J20: =I20 -> 30.65 | K20: =J20 -> 30.65
B21: (iv) Other financial assets | C21: 1215 | D21: 613 | E21: 929.78 | F21: 1605.02 | G21: =F21 -> 1605.02 | H21: =G21 -> 1605.02 | I21: =H21 -> 1605.02 | J21: =I21 -> 1605.02 | K21: =J21 -> 1605.02
B22: (c) Other current assets | C22: 1556 | D22: 1936 | E22: 1465.5 | F22: 2431.66 | G22: =F22 -> 2431.66 | H22: =G22 -> 2431.66 | I22: =H22 -> 2431.66 | J22: =I22 -> 2431.66 | K22: =J22 -> 2431.66
B23: Assets classified as held for sale | C23: 112 | D23: 40 | E23: 0.2 | F23: 0 | G23: =F23 -> 0 | H23: =G23 -> 0 | I23: =H23 -> 0 | J23: =I23 -> 0 | K23: =J23 -> 0
B24: Total current assets | C24: =SUM(C16:C23) -> 77903 | D24: =SUM(D16:D23) -> 71641 | E24: =SUM(E16:E23) -> 66584.09 | F24: =SUM(F16:F23) -> 95408.32 | G24: =SUM(G16:G23) -> 120454.46 | H24: =SUM(H16:H23) -> 141214.81 | I24: =SUM(I16:I23) -> 171220.89 | J24: =SUM(J16:J23) -> 196698.33 | K24: =SUM(K16:K23) -> 231848.7
A26: # | B26: Total assets | C26: =SUM(C24,C13) -> 94192 | D26: =SUM(D24,D13) -> 89921 | E26: =SUM(E24,E13) -> 84984.35 | F26: =SUM(F24,F13) -> 115171.45 | G26: =SUM(G24,G13) -> 140978.67 | H26: =SUM(H24,H13) -> 162698.31 | I26: =SUM(I24,I13) -> 193510.47 | J26: =SUM(J24,J13) -> 219627.03 | K26: =SUM(K24,K13) -> 255234.5
B28: Equity
B29: (a) Equity share capital | C29: 1131 | D29: 1131 | E29: 1131.29 | F29: 6787.72 | G29: =F29 -> 6787.72 | H29: =G29 -> 6787.72 | I29: =H29 -> 6787.72 | J29: =I29 -> 6787.72 | K29: =J29 -> 6787.72
B30: (b) Other equity | C30: 53876 | D30: 42431 | E30: 36591.17 | F30: 52913.98 | G30: =F30+'P&L'!G46 -> 72954.902 | H30: =G30+'P&L'!H46 -> 94625.795 | I30: =H30+'P&L'!I46 -> 118073.45 | J30: =I30+'P&L'!J46 -> 143458.03 | K30: =J30+'P&L'!K46 -> 170954.37
A31: # | B31: Total equity | C31: =SUM(C29:C30) -> 55007 | D31: =SUM(D29:D30) -> 43562 | E31: =SUM(E29:E30) -> 37722.46 | F31: =SUM(F29:F30) -> 59701.7 | G31: =SUM(G29:G30) -> 79742.622 | H31: =SUM(H29:H30) -> 101413.52 | I31: =SUM(I29:I30) -> 124861.17 | J31: =SUM(J29:J30) -> 150245.75 | K31: =SUM(K29:K30) -> 177742.09
B33: LIABILITIES
B34: Non-current liabilities
B35: (a) Financial liabilities - Lease liabilities | C35: 2347 | D35: 2495 | E35: 2846.96 | F35: 3305.32 | G35: =rBS!H38 -> 3305.32 | H35: =rBS!I38 -> 3305.32 | I35: =rBS!J38 -> 3305.32 | J35: =rBS!K38 -> 3305.32 | K35: =rBS!L38 -> 3305.32
B36: (b) Provisions | C36: 743 | D36: 832 | E36: 875.18 | F36: 939.22 | G36: =F36 -> 939.22 | H36: =G36 -> 939.22 | I36: =H36 -> 939.22 | J36: =I36 -> 939.22 | K36: =J36 -> 939.22
B37: (c) Other non-current liabilities | C37: 931 | D37: 1160 | E37: 1673.16 | F37: 2240.62 | G37: =F37 -> 2240.62 | H37: =G37 -> 2240.62 | I37: =H37 -> 2240.62 | J37: =I37 -> 2240.62 | K37: =J37 -> 2240.62
A38: # | B38: Total non-current liabilities | C38: =SUM(C35:C37) -> 4021 | D38: =SUM(D35:D37) -> 4487 | E38: =SUM(E35:E37) -> 5395.3 | F38: =SUM(F35:F37) -> 6485.16 | G38: =SUM(G35:G37) -> 6485.16 | H38: =SUM(H35:H37) -> 6485.16 | I38: =SUM(I35:I37) -> 6485.16 | J38: =SUM(J35:J37) -> 6485.16 | K38: =SUM(K35:K37) -> 6485.16
B40: Current liabilities
B41: (a) Financial liabilities
B42: (i) Lease liabilities | C42: 561 | D42: 690 | E42: 852.59 | F42: 972.96 | G42: =rBS!H39 -> 0 | H42: =rBS!I39 -> 0 | I42: =rBS!J39 -> 0 | J42: =rBS!K39 -> 0 | K42: =rBS!L39 -> 0
B43: (ii) Trade payables | C43: 25984 | D43: 31260 | E43: 29755.44 | F43: 33671.14 | G43: =rBS!$H$43*'P&L'!G10/365*2-BS!F43 -> 40410.402 | H43: =rBS!$H$43*'P&L'!H10/365*2-BS!G43 -> 40459.141 | I43: =rBS!$H$43*'P&L'!I10/365*2-BS!H43 -> 47823.654 | J43: =rBS!$H$43*'P&L'!J10/365*2-BS!I43 -> 48555.622 | K43: =rBS!$H$43*'P&L'!K10/365*2-BS!J43 -> 56666.762
B44: (iii) Other financial liabilities | C44: 2886 | D44: 3236 | E44: 3476.32 | F44: 4720.03 | G44: =F44 -> 4720.03 | H44: =G44 -> 4720.03 | I44: =H44 -> 4720.03 | J44: =I44 -> 4720.03 | K44: =J44 -> 4720.03
B45: (b) Other current liabilities | C45: 4256 | D45: 5092 | E45: 5906.04 | F45: 7132.42 | G45: =F45 -> 7132.42 | H45: =G45 -> 7132.42 | I45: =H45 -> 7132.42 | J45: =I45 -> 7132.42 | K45: =J45 -> 7132.42
...

Sheet CFS
B1: Particulars | C1: ='P&L'!C1 -> 44652 | D1: =EDATE(C1,12) -> 45017 | E1: =EDATE(D1,12) -> 45383 | F1: =EDATE(E1,12) -> 45748 | G1: =EDATE(F1,12) -> 46113 | H1: =EDATE(G1,12) -> 46478 | I1: =EDATE(H1,12) -> 46844 | J1: =EDATE(I1,12) -> 47209 | K1: =EDATE(J1,12) -> 47574
B2: A. CASH FLOW FROM OPERATING ACTIVITIES
A4: # | B4: =B6&"from Continuing Operation " -> Profit before taxfrom Continuing Operation | C4: ='P&L'!C23 -> 16316 | D4: ='P&L'!D23 -> 18203
B5: ='P&L'!B34 -> Loss from Discontinued Operations before tax | C5: ='P&L'!C34 -> -418 | D5: ='P&L'!D34 -> -42
B6: Profit before tax | C6: =SUM(C4:C5) -> 15898 | D6: =SUM(D4:D5) -> 18161 | E6: ='P&L'!E23 -> 20371.17 | F6: ='P&L'!F23 -> 29631.11 | G6: ='P&L'!G23 -> 26721.23 | H6: ='P&L'!H23 -> 28894.524 | I6: ='P&L'!I23 -> 31263.535 | J6: ='P&L'!J23 -> 33846.118 | K6: ='P&L'!K23 -> 36661.782
B8: Adjustments for
B9: Depreciation and amortisation expense | C9: 2612 | D9: 3004 | E9: 3643.69 | F9: 3803.57 | G9: ='P&L'!G18 -> 4305.2535 | H9: ='P&L'!H18 -> 4933.7589 | I9: ='P&L'!I18 -> 5619.8667 | J9: ='P&L'!J18 -> 6368.8844 | K9: ='P&L'!K18 -> 7186.6116
B10: Profit on sale of property, plant and equipment (net) | C10: -33 | D10: -7 | E10: -8.42 | F10: -33.1
B11: Interest income on bank deposits | C11: -1624 | D11: -2202 | E11: -1989.48 | F11: -2476.99
B12: Interest on lease liabilities | C12: 225 | D12: 225 | E12: 269.42 | F12: 304.59 | G12: ='P&L'!G22 -> 313.41851 | H12: ='P&L'!H22 -> 313.41851 | I12: ='P&L'!I22 -> 313.41851 | J12: ='P&L'!J22 -> 313.41851 | K12: ='P&L'!K22 -> 313.41851
B13: Property, plant and equipment written-off | C13: 1 | D13: 3 | E13: 3.21 | F13: 18.03
B14: Allowance for doubtful trade receivables, other assets and other financial assets | C14: 73 | D14: 48 | E14: -15.48 | F14: -127.68
B15: Trade receivables written-off | C15: 13 | D15: 19 | E15: 13.63 | F15: 1.71
B16: Provision for warranty expenses | C16: -94 | D16: 87 | E16: 136.95 | F16: 181.9
B17: Provision for service tax liability written-back | C17: -344
B18: Sundry advances written-off/(written-back) | C18: -1
B19: Unrealised (gain)/loss on foreign currency (net) | C19: 62 | D19: -19 | E19: 61.04 | F19: -200.17
C20: =SUM(C9:C19) -> 890 | D20: =SUM(D9:D19) -> 1158 | E20: =SUM(E9:E19) -> 2114.56 | F20: =SUM(F9:F19) -> 1471.86 | G20: =SUM(G9:G19) -> 4618.672 | H20: =SUM(H9:H19) -> 5247.1774 | I20: =SUM(I9:I19) -> 5933.2852 | J20: =SUM(J9:J19) -> 6682.3029 | K20: =SUM(K9:K19) -> 7500.0301
B22: Operating profit before change in operating assets and liabilities | C22: =C6+C20 -> 16788 | D22: =D6+D20 -> 19319 | E22: =E6+E20 -> 22485.73 | F22: =F6+F20 -> 31102.97 | G22: =G6+G20 -> 31339.902 | H22: =H6+H20 -> 34141.701 | I22: =I6+I20 -> 37196.82 | J22: =J6+J20 -> 40528.421 | K22: =K6+K20 -> 44161.812
B23: Changes in working capital
B24: Adjustment for (increase) / decrease in operating assets:
B25: Inventories | C25: 2238 | D25: -2262 | E25: 2468.08 | F25: -6340.37 | G25: =-(BS!G16-BS!F16) -> -2458.2518 | H25: =-(BS!H16-BS!G16) -> -3002.9317 | I25: =-(BS!I16-BS!H16) -> -3279.5355 | J25: =-(BS!J16-BS!I16) -> -3581.7878 | K25: =-(BS!K16-BS!J16) -> -3912.0869
B26: Trade receivables | C26: -3282 | D26: -1207 | E26: -2946.03 | F26: -5711.48 | G26: =-(BS!G18-BS!F18) -> 2696.9145 | H26: =-(BS!H18-BS!G18) -> -6776.8237 | I26: =-(BS!I18-BS!H18) -> 2321.109 | J26: =-(BS!J18-BS!I18) -> -7187.4764 | K26: =-(BS!K18-BS!J18) -> 1872.3508
B27: Other assets | C27: 122 | D27: -269 | E27: 369.32 | F27: -1154.45
B28: Other financial assets | C28: -186 | D28: 420 | E28: -257.92 | F28: -801.12
B29: Loans | C29: -30 | D29: 10 | E29: -4.6 | F29: -13.57
B31: Adjustment for increase/ (decrease) in operating liabilities:
B32: Trade payables | C32: -6941 | D32: 5233 | E32: -949.38 | F32: 4153.17 | G32: =BS!G43-BS!F43 -> 6739.2616 | H32: =BS!H43-BS!G43 -> 48.739368 | I32: =BS!I43-BS!H43 -> 7364.5127 | J32: =BS!J43-BS!I43 -> 731.96803 | K32: =BS!K43-BS!J43 -> 8111.14
B33: Provisions | C33: 60 | D33: 196 | E33: 181.39 | F33: 129.53
B34: Other liabilities | C34: 1105 | D34: 1002 | E34: 1327.05 | F34: 1793.84
B35: Other financial liabilities | C35: 121 | D35: 865 | E35: -320.53 | F35: 919.13
C36: =SUM(C25:C35) -> -6793 | D36: =SUM(D25:D35) -> 3988 | E36: =SUM(E25:E35) -> -132.62 | F36: =SUM(F25:F35) -> -7025.32 | G36: =SUM(G25:G35) -> 6977.9243 | H36: =SUM(H25:H35) -> -9731.016 | I36: =SUM(I25:I35) -> 6406.0863 | J36: =SUM(J25:J35) -> -10037.296 | K36: =SUM(K25:K35) -> 6071.4039
B37: Cash generated from operations | C37: =C22+C36 -> 9995 | D37: =D22+D36 -> 23307 | E37: =E22+E36 -> 22353.11 | F37: =F22+F36 -> 24077.65 | G37: =G22+G36 -> 38317.826 | H37: =H22+H36 -> 24410.685 | I37: =I22+I36 -> 43602.906 | J37: =J22+J36 -> 30491.125 | K37: =K22+K36 -> 50233.216
B38: Net income tax (paid)/refunds | C38: -4016 | D38: -4425 | E38: -5698.5 | F38: -7538.73 | G38: =-'P&L'!G29 -> -6680.3074 | H38: =-'P&L'!H29 -> -7223.6309 | I38: =-'P&L'!I29 -> -7815.8836 | J38: =-'P&L'!J29 -> -8461.5296 | K38: =-'P&L'!K29 -> -9165.4456
A40: # | B40: Net cash inflow from operating activities (A) | C40: =SUM(C37:C38) -> 5979 | D40: =SUM(D37:D38) -> 18882 | E40: =SUM(E37:E38) -> 16654.61 | F40: =SUM(F37:F38) -> 16538.92 | G40: =SUM(G37:G38) -> 31637.519 | H40: =SUM(H37:H38) -> 17187.054 | I40: =SUM(I37:I38) -> 35787.022 | J40: =SUM(J37:J38) -> 22029.595 | K40: =SUM(K37:K38) -> 41067.771
B42: B. CASH FLOWS FROM INVESTING ACTIVITIES
B44: Purchase of property, plant and equipment and intangible assets (including Capital work-in-progress and Intangible assets under development) | C44: -2733 | D44: -5171 | E44: -2421.25 | F44: -3393.26 | G44: =-(rBS!H4+rBS!H12) -> -5371.7697 | H44: =-(rBS!I4+rBS!I12) -> -5863.9784 | I44: =-(rBS!J4+rBS!J12) -> -6401.525 | J44: =-(rBS!K4+rBS!K12) -> -6988.6137 | K44: =-(rBS!L4+rBS!L12) -> -7629.8414
B45: Proceeds from government grant | C45: 296 | D45: 197 | E45: 208.06 | F45: 593.12 | G45: =305.428376116586 -> 305.42838
B46: Proceeds from sale of property, plant and equipment (including intangible assets under development) | C46: 38 | D46: 33 | E46: 19.14 | F46: 47.7
B47: Interest income on bank deposits | C47: 1667 | D47: 2202 | E47: 1989.48 | F47: 2476.99
...

Sheet DCF
B2: Assumptions
B3: Tax Rate | D3: ='rP&L'!H23 -> 0.25
B4: Discount Rate | D4: =WACC!D21 -> 0.12709048
B5: Perpetural Growth Rate | D5: 0.05
B6: EV/EBITDA Mulltiple | D6: 30.27
B7: Transaction Date | D7: =TODAY() -> 46195
B8: Fiscal Year End | D8: ='P&L'!G1 -> 46113
B9: Current Price | D9: 1561.01
B10: Shares Outstanding | D10: ='P&L'!K52 -> 678772392
B11: Debt | D11: =BS!F35+BS!F42 -> 4278.28
B12: Cash | D12: =BS!F19 -> 37414.73
B13: Capex | D13: =rBS!G4+rBS!G12 -> 2960.83
B15: Discounted Cash Flow | D15: Entry | E15: =YEAR(E16) -> 2026 | F15: =YEAR(F16) -> 2027 | G15: =YEAR(G16) -> 2028 | H15: =YEAR(H16) -> 2029 | I15: =YEAR(I16) -> 2030 | J15: Exit | L15: Terminal Value
B16: Date | D16: =D7 -> 46195 | E16: =DATE(YEAR($D$8)+E17,6,30) -> 46203 | F16: =DATE(YEAR($D$8)+F17,6,30) -> 46568 | G16: =DATE(YEAR($D$8)+G17,6,30) -> 46934 | H16: =DATE(YEAR($D$8)+H17,6,30) -> 47299 | I16: =DATE(YEAR($D$8)+I17,6,30) -> 47664 | J16: =I16 -> 47664 | L16: Perpetural Growth | N16: =(I24*(1+D5))/(D4-D5) -> 251713.66
B17: Time Periods | E17: 0 | F17: =E17+1 -> 1 | G17: =F17+1 -> 2 | H17: =G17+1 -> 3 | I17: =H17+1 -> 4 | L17: EV/EBITDA | N17: =D6*(I19+I21) -> 1226350.1
B18: Year Fraction | E18: =YEARFRAC(D16,E16) -> 0.022222222 | F18: =YEARFRAC(E16,F16) -> 1 | G18: =YEARFRAC(F16,G16) -> 1 | H18: =YEARFRAC(G16,H16) -> 1 | I18: =YEARFRAC(H16,I16) -> 1 | L18: Average | N18: =AVERAGE(N16:N17) -> 739031.88
B19: EBIT | E19: ='P&L'!G19 -> 24218.32 | F19: ='P&L'!H19 -> 26203.394 | G19: ='P&L'!I19 -> 28371.607 | H19: ='P&L'!J19 -> 30739.972 | I19: ='P&L'!K19 -> 33327.102
B20: Less: Cash Taxes | E20: =E19*$D$3 -> 6054.5799 | F20: =F19*$D$3 -> 6550.8486 | G20: =G19*$D$3 -> 7092.9017 | H20: =H19*$D$3 -> 7684.9931 | I20: =I19*$D$3 -> 8331.7755
B21: Plus: D&A | E21: ='P&L'!G18 -> 4305.2535 | F21: ='P&L'!H18 -> 4933.7589 | G21: ='P&L'!I18 -> 5619.8667 | H21: ='P&L'!J18 -> 6368.8844 | I21: ='P&L'!K18 -> 7186.6116
B22: Less: Capex | E22: =(rBS!H4+rBS!H12) -> 5371.7697 | F22: =(rBS!I4+rBS!I12) -> 5863.9784 | G22: =(rBS!J4+rBS!J12) -> 6401.525 | H22: =(rBS!K4+rBS!K12) -> 6988.6137 | I22: =(rBS!L4+rBS!L12) -> 7629.8414
B23: Less: Changes in NWC | E23: 6977.9243 | F23: -9731.016 | G23: 6406.0863 | H23: -10037.296 | I23: 6071.4039
B24: Unlevered FCF | E24: =E19-E20+E21-E22-E23 -> 10119.299 | F24: =F19-F20+F21-F22-F23 -> 28453.342 | G24: =G19-G20+G21-G22-G23 -> 14090.96 | H24: =H19-H20+H21-H22-H23 -> 32472.546 | I24: =I19-I20+I21-I22-I23 -> 18480.693
B25: (Entry)/Exit | D25: =-H33 -> -1.0595705e+12 | J25: =N18 -> 739031.88
B26: Transaction CF | D26: 0 | E26: =(E25+E24)*E18 -> 224.87332 | F26: =(F25+F24)*F18 -> 28453.342 | G26: =(G25+G24)*G18 -> 14090.96 | H26: =(H25+H24)*H18 -> 32472.546 | I26: =(I25+I24)*I18 -> 18480.693 | J26: =J25+J24 -> 739031.88
B27: Transaction CF | D27: =D25+D24 -> -1.0595705e+12 | E27: =(E25+E24)*E18 -> 224.87332 | F27: =(F25+F24)*F18 -> 28453.342 | G27: =(G25+G24)*G18 -> 14090.96 | H27: =(H25+H24)*H18 -> 32472.546 | I27: =(I25+I24)*I18 -> 18480.693 | J27: =J25 -> 739031.88
D28: =D27 -> -1.0595705e+12 | E28: =E27*1000000 -> 2.2487332e+08 | F28: =F27*1000000 -> 2.8453342e+10 | G28: =G27*1000000 -> 1.409096e+10 | H28: =H27*1000000 -> 3.2472546e+10 | I28: =I27*1000000 -> 1.8480693e+10 | J28: =J27*1000000 -> 7.3903188e+11
B29: Intrinsic Value | G29: Market Value | L29: Rate of Return
B30: Enterprise Value | D30: =XNPV(D4,D26:J26,D16:J16) -> 527105.66 | G30: Market Cap | H30: =D10*D9 -> 1.0595705e+12 | L30: Target Price Downside | N30: =D35/I35-1 -> -0.47125547
B31: Plus: Cash | D31: =+D12 -> 37414.73 | G31: Plus: Debt | I31: =D11 -> 4278.28 | L31: Internal Rate of Return (IRR) | N31: =XIRR((D28:J28),D16:J16) -> -0.060501799
B32: Less: Debt | D32: =+D11 -> 4278.28 | G32: Less: Cash | I32: =+D12 -> 37414.73
B33: Equity Value | D33: =D30+D31-D32 -> 560242.11 | G33: Enterprise Value | H33: =(H30+I31-I32) -> 1.0595705e+12 | L33: Market Value vs Intrinsic Value
L34: Market Value | N34: =I35 -> 1561.01
B35: Equity Value/Share | D35: =D33/D10*1000000 -> 825.37551 | G35: Equity Value/Share | I35: =D9 -> 1561.01 | L35: Downside | N35: =D35-I35 -> -735.63449
L36: Intrinsic Value | N36: =SUM(N34:N35) -> 825.37551

Sheet WACC
B2: WACC Calculator
B4: WACC Calculation | F4: Comparable Companies Unlevered Beta
B5: Capital Structure | F5: Company | G5: Levered Beta | H5: Debt | I5: Equity | J5: Debt/Equity | K5: Tax Rate | L5: Unlevered Beta
B6: Debt to Total Capitalization | D6: =SUM(BS!F35,BS!F42)/SUM(BS!F35,BS!F42,BS!F29:F30) -> 0.066869042 | F6: Titan Company | G6: 0.8 | H6: 12465 | I6: 349219.55 | J6: =H6/I6 -> 0.035693878 | K6: 0.26416759 | L6: =G6/((1+(1-K6)*J6)) -> 0.77952597
B7: Equity to Total Capitalization | D7: =SUM(BS!F29:F30)/SUM(BS!F29:F30,BS!F35,BS!F42) -> 0.93313096 | F7: Asian Paints | G7: 0.75 | H7: 3557.09 | I7: 269400.59 | J7: =H7/I7 -> 0.01320372 | K7: 0.27304348 | L7: =G7/((1+(1-K7)*J7)) -> 0.74286954
B8: Debt / Equity | D8: =D6/D7 -> 0.071660941 | F8: LG Electronics | G8: 1.1 | H8: 472.59 | I8: 105996.76 | J8: =H8/I8 -> 0.0044585325 | K8: ='P&L'!F29/'P&L'!F23 -> 0.2564072 | L8: =G8/((1+(1-K8)*J8)) -> 1.0963652
F9: Havells India | G9: 1.05 | H9: 285.98 | I9: 89849.09 | J9: =H9/I9 -> 0.0031828926 | K9: 0.2613678 | L9: =G9/((1+(1-K9)*J9)) -> 1.0475373
B10: Cost of Equity Calculation | F10: Dixon Technolog. | G10: 1.4 | H10: 1389.12 | I10: 77962.01 | J10: =H10/I10 -> 0.017817909 | K10: 0.21481717 | L10: =G10/((1+(1-K10)*J10)) -> 1.3806838
B11: Risk Free Rate | D11: 0.066 | F11: Berger Paints | G11: 0.85 | H11: 697.33 | I11: 63234.25 | J11: =H11/I11 -> 0.011027726 | K11: 0.24588293 | L11: =G11/((1+(1-K11)*J11)) -> 0.84298953
B12: Equity Risk Premium | D12: 0.06 | F12: Kalyan Jewellers | G12: 1.2 | H12: 5334.96 | I12: 50130.63 | J12: =H12/I12 -> 0.10642116 | K12: 0.25576282 | L12: =G12/((1+(1-K12)*J12)) -> 1.1119321
B13: Levered Beta | D13: =L15*(1+(1-D18)*D8) -> 1.1033569 | F13: Voltas | G13: 1.15 | H13: 1755 | I13: 45930.15 | J13: =H13/I13 -> 0.038210195 | K13: 0.29936595 | L13: 0.96925501
B14: Cost of Equity | D14: =D11+D12*D13 -> 0.13220141 | F14: Blue Star | G14: 1.1 | H14: 1030.19 | I14: 36302.44 | J14: =H14/I14 -> 0.028377982 | K14: 0.2467099 | L14: 1.4427336
F15: Median | G15: =MEDIAN(G6:G14) -> 1.1 | J15: =MEDIAN(J6:J14) -> 0.017817909 | L15: =MEDIAN(L6:L14) -> 1.0475373
B16: Cost of Debt Calculation
B17: Cost of Debt | D17: 0.075
B18: Tax Rate | D18: =K8 -> 0.2564072
B19: After-Tax Cost of Debt | D19: =D17*(1-D18) -> 0.05576946
B21: WACC | D21: =(D14*D7)+(D19*D6) -> 0.12709048

Sheet rP&L
D1: ='P&L'!C1 -> 44652 | E1: ='P&L'!D1 -> 45017 | F1: ='P&L'!E1 -> 45383 | G1: ='P&L'!F1 -> 45748 | H1: ='P&L'!G1 -> 46113 | I1: ='P&L'!H1 -> 46478 | J1: ='P&L'!I1 -> 46844 | K1: ='P&L'!J1 -> 47209 | L1: ='P&L'!K1 -> 47574
B2: REVENUE (growth rate)
B3: Domestic | D3: 160169 | E3: 189102 | F3: 203635 | G3: 229143.82 | H3: =G3*(1+$H$4) -> 249766.76 | I3: =H3*(1+$H$4) -> 272245.77 | J3: =I3*(1+$H$4) -> 296747.89 | K3: =J3*(1+$H$4) -> 323455.2 | L3: =K3*(1+$H$4) -> 352566.17
E4: =E3/D3-1 -> 0.18064045 | F4: =F3/E3-1 -> 0.076852704 | G4: =G3/F3-1 -> 0.12526737 | H4: 0.09
B5: Africa | D5: 1386 | E5: 1777 | F5: 1693 | G5: 2414.24 | H5: =G5*(1+$H$6) -> 2655.664 | I5: =H5*(1+$H$6) -> 2921.2304 | J5: =I5*(1+$H$6) -> 3213.3534 | K5: =J5*(1+$H$6) -> 3534.6888 | L5: =K5*(1+$H$6) -> 3888.1577
E6: =E5/D5-1 -> 0.28210678 | F6: =F5/E5-1 -> -0.047270681 | G6: =G5/F5-1 -> 0.42601299 | H6: 0.1
B7: Europe | D7: 7 | E7: 11 | F7: 1 | G7: 0.06 | H7: =G7*(1+$H$8) -> 0.066 | I7: =H7*(1+$H$8) -> 0.0726 | J7: =I7*(1+$H$8) -> 0.07986 | K7: =J7*(1+$H$8) -> 0.087846 | L7: =K7*(1+$H$8) -> 0.0966306
E8: =E7/D7-1 -> 0.57142857 | F8: =F7/E7-1 -> -0.90909091 | G8: =G7/F7-1 -> -0.94 | H8: 0.1
B9: Asia(excluding India) | D9: 6716 | E9: 7728 | F9: 8163 | G9: 12100.86 | H9: =G9*(1+$H$10) -> 13552.963 | I9: =H9*(1+$H$10) -> 15179.319 | J9: =I9*(1+$H$10) -> 17000.837 | K9: =J9*(1+$H$10) -> 19040.937 | L9: =K9*(1+$H$10) -> 21325.85
E10: =E9/D9-1 -> 0.15068493 | F10: =F9/E9-1 -> 0.05628882 | G10: =G9/F9-1 -> 0.48240353 | H10: 0.12
B11: Others | D11: 64 | E11: 28 | F11: 28 | G11: 7.4 | H11: =G11*(1+$H$12) -> 8.14 | I11: =H11*(1+$H$12) -> 8.954 | J11: =I11*(1+$H$12) -> 9.8494 | K11: =J11*(1+$H$12) -> 10.83434 | L11: =K11*(1+$H$12) -> 11.917774
E12: =E11/D11-1 -> -0.5625 | F12: =F11/E11-1 -> 0 | G12: =G11/F11-1 -> -0.73571429 | H12: 0.1
B14: Other income (Cagar) | D14: ='P&L'!C21 -> 2038 | E14: ='P&L'!D21 -> 2440 | F14: ='P&L'!E21 -> 2051.18 | G14: ='P&L'!F21 -> 2639.9 | H14: =G14*(1+$H$15) -> 2816.3284 | I14: =H14*(1+$H$15) -> 3004.5478 | J14: =I14*(1+$H$15) -> 3205.3462 | K14: =J14*(1+$H$15) -> 3419.5643 | L14: =K14*(1+$H$15) -> 3648.0988
H15: =(G14/D14)^(1/4) -1 -> 0.066831484
B17: COGS (% OF REVENUE ) | D17: ='P&L'!C10/'P&L'!C3 -> 0.70098371 | E17: ='P&L'!D10/'P&L'!D3 -> 0.70618588 | F17: ='P&L'!E10/'P&L'!E3 -> 0.69924026 | G17: ='P&L'!F10/'P&L'!F3 -> 0.68044217 | H17: =AVERAGE(D17:G17) -> 0.696713
B19: TOTAL EXPENSES(% OF REVENUE) | D19: ='P&L'!C15/'P&L'!C3 -> 0.19751458 | E19: ='P&L'!D15/'P&L'!D3 -> 0.19820183 | F19: ='P&L'!E15/'P&L'!E3 -> 0.19655999 | G19: ='P&L'!F15/'P&L'!F3 -> 0.19191921 | H19: =AVERAGE(D19:G19) -> 0.1960489
B21: INTEREST | D21: ='P&L'!C22/BS!C35 -> 0.095867064 | E21: ='P&L'!D22/BS!D35 -> 0.090581162 | F21: ='P&L'!E22/BS!E35 -> 0.10012434 | G21: ='P&L'!F22/BS!F35 -> 0.092717195 | H21: =AVERAGE(D21:G21) -> 0.094822441
B23: TAX | D23: ='P&L'!C29/'P&L'!C23 -> 0.26109341 | E23: ='P&L'!D29/'P&L'!D23 -> 0.25946273 | F23: ='P&L'!E29/'P&L'!E23 -> 0.2582321 | G23: ='P&L'!F29/'P&L'!F23 -> 0.2564072 | H23: 0.25

Sheet rBS
D1: ='P&L'!C1 -> 44652 | E1: ='P&L'!D1 -> 45017 | F1: ='P&L'!E1 -> 45383 | G1: ='P&L'!F1 -> 45748 | H1: ='P&L'!G1 -> 46113 | I1: ='P&L'!H1 -> 46478 | J1: ='P&L'!I1 -> 46844 | K1: ='P&L'!J1 -> 47209 | L1: ='P&L'!K1 -> 47574
B2: TANGIBLES
B3: Opening Gross PP&E | D3: 22502 | E3: =D5 -> 24519 | F3: =E5 -> 29776 | G3: =F5 -> 32453.23 | H3: =G5 -> 35362.87 | I3: =H5 -> 40682.542 | J3: =I5 -> 46489.649 | K3: =J5 -> 52829.089 | L3: =K5 -> 59749.924
B4: Capex on PP&E | D4: 2017 | E4: 5257 | F4: 2676.76 | G4: 2909.64 | H4: ='P&L'!G$3*$H$8 -> 5319.6719 | I4: ='P&L'!H$3*$H$8 -> 5807.107 | J4: ='P&L'!I$3*$H$8 -> 6339.4402 | K4: ='P&L'!J$3*$H$8 -> 6920.835 | L4: ='P&L'!K$3*$H$8 -> 7555.8439
B5: Closing Gross PP&E | D5: =SUM(D3:D4) -> 24519 | E5: =SUM(E3:E4) -> 29776 | F5: =SUM(F3:F4)+0.47 -> 32453.23 | G5: =SUM(G3:G4) -> 35362.87 | H5: =SUM(H3:H4) -> 40682.542 | I5: =SUM(I3:I4) -> 46489.649 | J5: =SUM(J3:J4) -> 52829.089 | K5: =SUM(K3:K4) -> 59749.924 | L5: =SUM(L3:L4) -> 67305.768
B6: Accum Dep | D6: 14132 | E6: =D6+SUM(E19,E20)-10-241-399 -> 16448 | F6: =E6+SUM(F19,F20)-416.93-13.1-270.51 -> 19347.8 | G6: =F6+SUM(G19,G20)-330.26-608.63 -> 22166.17 | H6: =G6+SUM(H21) -> 26421.855 | I6: =H6+SUM(I21) -> 31300.221 | J6: =I6+SUM(J21) -> 36858.338 | K6: =J6+SUM(K21) -> 43158.531 | L6: =K6+SUM(L21) -> 50268.875
B7: Net PP&E | D7: =D5-D6 -> 10387 | E7: =E5-E6 -> 13328 | F7: =F5-F6 -> 13105.43 | G7: =G5-G6 -> 13196.7 | H7: =H5-H6 -> 14260.687 | I7: =I5-I6 -> 15189.428 | J7: =J5-J6 -> 15970.751 | K7: =K5-K6 -> 16591.393 | L7: =L5-L6 -> 17036.893
B8: Capex (% revenue ) | D8: =D4/'P&L'!C$3 -> 0.011981561 | E8: =E4/'P&L'!D$3 -> 0.026464162 | F8: =F4/'P&L'!E$3 -> 0.012536343 | G8: =G4/'P&L'!F$3 -> 0.011941081 | H8: 0.02
B10: INTANGIBLES
B11: Opening Gross Intangibles | D11: 279 | E11: =D13 -> 321 | F11: =E13 -> 370 | G11: =F13 -> 386.49 | H11: =G13 -> 437.68 | I11: =H13 -> 489.77779 | J11: =I13 -> 546.64923 | K11: =J13 -> 608.73404 | L11: =K13 -> 676.51269
B12: Additions to Intangibles | D12: =52-10 -> 42 | E12: 49 | F12: =27.8-0.8-11+0.49 -> 16.49 | G12: =(57.73-0.09)-6.45 -> 51.19 | H12: ='P&L'!G$3*rBS!$H$16 -> 52.097787 | I12: ='P&L'!H3*rBS!$H$16 -> 56.871444 | J12: ='P&L'!I3*rBS!$H$16 -> 62.084808 | K12: ='P&L'!J3*rBS!$H$16 -> 67.778652 | L12: ='P&L'!K3*rBS!$H$16 -> 73.997561
B13: Closing Gross Intangibles | D13: =SUM(D11:D12) -> 321 | E13: =SUM(E11:E12) -> 370 | F13: =SUM(F11:F12) -> 386.49 | G13: =SUM(G11:G12) -> 437.68 | H13: =SUM(H11:H12) -> 489.77779 | I13: =SUM(I11:I12) -> 546.64923 | J13: =SUM(J11:J12) -> 608.73404 | K13: =SUM(K11:K12) -> 676.51269 | L13: =SUM(L11:L12) -> 750.51025
B14: Accum Amort | D14: 233 | E14: =D14+E24 -> 271 | F14: =E14+F24-10.95+0.03 -> 303.43 | G14: =F14+G24-6.45 -> 343.29 | H14: =G14+H24 -> 392.85859 | I14: =H14+I24 -> 448.2511 | J14: =I14+J24 -> 510.00132 | K14: =J14+K24 -> 578.69217 | L14: =K14+L24 -> 654.96034
B15: Net Intangibles | D15: =D13-D14 -> 88 | E15: =E13-E14 -> 99 | F15: =F13-F14 -> 83.06 | G15: =G13-G14 -> 94.39 | H15: =H13-H14 -> 96.919201 | I15: =I13-I14 -> 98.398126 | J15: =J13-J14 -> 98.732721 | K15: =K13-K14 -> 97.820523 | L15: =L13-L14 -> 95.549911
B16: Capex (% revenue ) | D16: =D12/'P&L'!C$3 -> 0.00024949211 | E16: =E12/'P&L'!D$3 -> 0.00024666996 | F16: =F12/'P&L'!E$3 -> 7.7229299e-05 | G16: =G12/'P&L'!F$3 -> 0.00021008233 | H16: =AVERAGE(D16:G16) -> 0.00019586842
B18: D&A
B19: Owned | D19: 2015 | E19: 2350 | F19: 2829.52 | G19: 2869.38
B20: Right of use of issue | D20: 536 | E20: 616 | F20: 770.82 | G20: 887.88
B21: DEP | D21: =SUM(D19:D20) -> 2551 | E21: =SUM(E19:E20) -> 2966 | F21: =SUM(F19:F20) -> 3600.34 | G21: =SUM(G19:G20) -> 3757.26 | H21: =AVERAGE(G5:H5)*$H$22 -> 4255.6849 | I21: =AVERAGE(H5:I5)*$H$22 -> 4878.3664 | J21: =AVERAGE(I5:J5)*$H$22 -> 5558.1165 | K21: =AVERAGE(J5:K5)*$H$22 -> 6300.1935 | L21: =AVERAGE(K5:L5)*$H$22 -> 7110.3435
E22: =E21/AVERAGE(D5:E5) -> 0.109255 | F22: =F21/AVERAGE(E5:F5) -> 0.11571218 | G22: =G21/AVERAGE(F5:G5) -> 0.11080732 | H22: =AVERAGE(E22:G22) -> 0.11192483
B24: amortisation | D24: 33 | E24: 38 | F24: 43.35 | G24: 46.31 | H24: =AVERAGE(G13:H13)*$H$25 -> 49.568587 | I24: =AVERAGE(H13:I13)*$H$25 -> 55.392518 | J24: =AVERAGE(I13:J13)*$H$25 -> 61.750213 | K24: =AVERAGE(J13:K13)*$H$25 -> 68.69085 | L24: =AVERAGE(K13:L13)*$H$25 -> 76.268172
D25: =D24/D13 -> 0.10280374 | E25: =E24/E13 -> 0.1027027 | F25: =F24/F13 -> 0.11216332 | G25: =G24/G13 -> 0.1058079 | H25: =AVERAGE(E25:G25) -> 0.1068913
B26: TOTAL | D26: ='P&L'!C18 -> 2584 | E26: ='P&L'!D18 -> 3004 | F26: ='P&L'!E18 -> 3643.69 | G26: ='P&L'!F18 -> 3803.57 | H26: =H24+H21 -> 4305.2535 | I26: =I24+I21 -> 4933.7589 | J26: =J24+J21 -> 5619.8667 | K26: =K24+K21 -> 6368.8844 | L26: =L24+L21 -> 7186.6116
B28: CWIP | D28: =BS!C4 -> 1024 | E28: =BS!D4 -> 243 | F28: =BS!E4 -> 242.05 | G28: =BS!F4 -> 753.12
D29: =D28/D7 -> 0.098584769 | E29: =E28/E7 -> 0.018232293 | F29: =F28/F7 -> 0.018469444 | G29: =G28/G7 -> 0.057068813 | H29: =AVERAGE(E29:G29) -> 0.03125685
B31: Under Development (intang) | D31: =BS!C6 -> 6 | E31: =BS!D6 -> 3 | F31: =BS!E6 -> 2.49 | G31: =BS!F6 -> 0
D32: =D31/D15 -> 0.068181818 | E32: =E31/E15 -> 0.03030303 | F32: =F31/F15 -> 0.029978329 | G32: =G31/G15 -> 0 | H32: =AVERAGE(E32:G32) -> 0.020093786
B34: INVENTORIES | D34: =BS!C16 -> 24094 | E34: =BS!D16 -> 26410 | F34: =BS!E16 -> 23974.18 | G34: =BS!F16 -> 30314.55
D35: =D34/'P&L'!C3 -> 0.1431253 | E35: =E34/'P&L'!D3 -> 0.13295007 | F35: =F34/'P&L'!E3 -> 0.11228072 | G35: =G34/'P&L'!F3 -> 0.12441006 | H35: =AVERAGE(E35:G35) -> 0.12321362
B37: DEBT
B38: LONG | D38: =BS!C35 -> 2347 | E38: =BS!D35 -> 2495 | F38: =BS!E35 -> 2846.96 | G38: =BS!F35 -> 3305.32 | H38: =G38 -> 3305.32 | I38: =H38 -> 3305.32 | J38: =I38 -> 3305.32 | K38: =J38 -> 3305.32 | L38: =K38 -> 3305.32
B39: SHORT | D39: =BS!C42 -> 561 | E39: =BS!D42 -> 690 | F39: =BS!E42 -> 852.59 | G39: =BS!F42 -> 972.96
B40: TOTAL | D40: =SUM(D38:D39) -> 2908 | E40: =SUM(E38:E39) -> 3185 | F40: =SUM(F38:F39) -> 3699.55 | G40: =SUM(G38:G39) -> 4278.28 | H40: =SUM(H38:H39) -> 3305.32 | I40: =SUM(I38:I39) -> 3305.32 | J40: =SUM(J38:J39) -> 3305.32 | K40: =SUM(K38:K39) -> 3305.32 | L40: =SUM(L38:L39) -> 3305.32
B42: Days Sales Outstanding | E42: =AVERAGE(BS!C18:F18)/('P&L'!D3/365) -> 32.333386 | F42: =AVERAGE(BS!D18:E18)/('P&L'!E3/365) -> 28.176053 | G42: =AVERAGE(BS!E18:F18)/('P&L'!F3/365) -> 31.143814 | H42: =AVERAGE(E42:G42) -> 30.551084
B43: Payable Days | E43: =AVERAGE(BS!C43:D43)/('P&L'!D10/365) -> 74.472167 | F43: =AVERAGE(BS!D43:E43)/('P&L'!E10/365) -> 74.582619 | G43: =AVERAGE(BS!E43:F43)/('P&L'!F10/365) -> 69.814773 | H43: =AVERAGE(E43:G43) -> 72.95652

Sheet rdcf
C1: =EDATE('P&L'!F1,12) -> 46113 | D1: =EDATE(C1,12) -> 46478 | E1: =EDATE(D1,12) -> 46844 | F1: =EDATE(E1,12) -> 47209 | G1: =EDATE(F1,12) -> 47574 | H1: TV
C2: 1 | D2: 2 | E2: 3 | F2: 4 | G2: 5
B3: EBIT | C3: ='P&L'!G19 -> 24218.32 | D3: ='P&L'!H19 -> 26203.394 | E3: ='P&L'!I19 -> 28371.607 | F3: ='P&L'!J19 -> 30739.972 | G3: ='P&L'!K19 -> 33327.102 | J3: Terminal Growth | L3: 0.05
B4: NOPAT | C4: =rdcf!C3*(1-'rP&L'!$H$23) -> 18163.74 | D4: =rdcf!D3*(1-'rP&L'!$H$23) -> 19652.546 | E4: =rdcf!E3*(1-'rP&L'!$H$23) -> 21278.705 | F4: =rdcf!F3*(1-'rP&L'!$H$23) -> 23054.979 | G4: =rdcf!G3*(1-'rP&L'!$H$23) -> 24995.327 | J4: WACC | L4: =WACC!D21 -> 0.12709048
B5: D&A | C5: ='P&L'!G18 -> 4305.2535 | D5: ='P&L'!H18 -> 4933.7589 | E5: ='P&L'!I18 -> 5619.8667 | F5: ='P&L'!J18 -> 6368.8844 | G5: ='P&L'!K18 -> 7186.6116
B6: CHANGE IN WC | C6: =SUM(CFS!G25:G35) -> 6977.9243 | D6: =SUM(CFS!H25:H35) -> -9731.016 | E6: =SUM(CFS!I25:I35) -> 6406.0863 | F6: =SUM(CFS!J25:J35) -> -10037.296 | G6: =SUM(CFS!K25:K35) -> 6071.4039
B7: CAPEX | C7: =-(rBS!H4+rBS!H12) -> -5371.7697 | D7: =-(rBS!I4+rBS!I12) -> -5863.9784 | E7: =-(rBS!J4+rBS!J12) -> -6401.525 | F7: =-(rBS!K4+rBS!K12) -> -6988.6137 | G7: =-(rBS!L4+rBS!L12) -> -7629.8414
B9: FCFF | C9: =SUM(C4:C7) -> 24075.148 | D9: =SUM(D4:D7) -> 8991.3103 | E9: =SUM(E4:E7) -> 26903.133 | F9: =SUM(F4:F7) -> 12397.954 | G9: =SUM(G4:G7) -> 30623.501 | H9: =G9*(1+L3)/(L4-L3) -> 417103.05
B11: PV OF FCFF AND TV | C11: =PV($L$4,C2,,-C9) -> 21360.439 | D11: =PV($L$4,D2,,-D9) -> 7077.9163 | E11: =PV($L$4,E2,,-E9) -> 18789.988 | F11: =PV($L$4,F2,,-F9) -> 7682.7179 | G11: =PV($L$4,G2,,-G9) -> 16836.853 | H11: =PV($L$4,G2,,-H9) -> 229323.97
B13: EV | C13: =SUM(C11:H11) -> 301071.89 | E13: Sensitivity Analysis- Value per Share
B15: DEBT | C15: =BS!F35+BS!F42 -> 4278.28 | G15: WACC
B16: CASH | C16: =BS!F19 -> 37414.73 | E16: Terminal Growth | F16: =C18 -> 492.37173 | G16: 0.11 | H16: 0.1271 | I16: 0.13 | J16: 0.14
B17: Equity value | C17: =C13-C15+C16 -> 334208.34 | F17: 0.04 | G17: 557.0973 | H17: 450.68301 | I17: 436.70167 | J17: 394.81373
B18: intrinsic value | C18: =(C17*1000000)/'P&L'!K52 -> 492.37173 | F18: 0.05 | G18: 627.85757 | H18: 492.31319 | I18: 475.13291 | J18: 424.49407
F19: 0.06 | G19: 726.92194 | H19: 546.35178 | I19: 524.54451 | J19: 461.59448
F20: 0.07 | G20: 875.5185 | H20: 619.31806 | I20: 590.42663 | J20: 509.29501
F22: Current Share Price | J22: 1561.01
F24: Discount/Premium | J24: =J22/C15 -> 0.36486859
